Workbook
Name _____BVS1: #REF!
Name _____BVS2: #REF!
Name _____HSH1: #REF!
Name _____HSH2: #REF!
Name _____JS1: #REF!
Name _____JS2: #REF!
Name _____LS1: #REF!
Name _____LS2: #REF!
Name _____LS3: #REF!
Name _____LS4: #REF!
Name _____NP1: #REF!
Name _____NP2: #REF!
Name _____NS1: #REF!
Name _____NS2: #REF!
Name _____NS3: #REF!
Name _____NS4: #REF!
Name _____NSH1: #REF!
Name _____NSH2: #REF!
Name _____pa1: #REF!
Name _____pa2: #REF!
Name _____PE1: #REF!
Name _____PE10: #REF!
Name _____PE11: #REF!
Name _____PE12: #REF!
Name _____PE13: #REF!
Name _____PE14: #REF!
Name _____PE15: #REF!
Name _____PE16: #REF!
Name _____PE17: #REF!
Name _____PE18: #REF!
Name _____PE19: #REF!
Name _____PE2: #REF!
Name _____PE20: #REF!
Name _____PE21: #REF!
Name _____PE22: #REF!
Name _____PE23: #REF!
Name _____PE24: #REF!
Name _____PE25: #REF!
Name _____PE26: #REF!
Name _____PE27: #REF!
Name _____PE28: #REF!
Name _____PE29: #REF!
Name _____PE3: #REF!
Name _____PE30: #REF!
Name _____PE31: #REF!
Name _____PE32: #REF!
Name _____PE33: #REF!
Name _____PE34: #REF!
Name _____PE35: #REF!
Name _____PE36: #REF!
Name _____PE37: #REF!
Name _____PE38: #REF!
Name _____PE39: #REF!
Name _____PE4: #REF!
Name _____PE40: #REF!
Name _____PE41: #REF!
Name _____PE42: #REF!
Name _____PE43: #REF!
Name _____PE44: #REF!
Name _____PE45: #REF!

Sheet 표지
A8: 소프트웨어 산출 내역서
A9: 산림공간 디지털 플랫폼 구축 사업
A16: 2025.1
A31: ="설계금액 : "&NUMBERSTRING(A32,1)&"원 정" -> 설계금액 : 육십사억사천만원 정
A32: =총괄표!E16 -> 6440000000
A35: 산 림 청

Sheet 총괄표
B1: 산림공간 디지털 플랫폼 구축 사업 산출내역서
B3: 구분 | E3: 금액(원) | F3: 비고
B4: 응용 SW 개발 | C4: 1. 2D플랫폼 구축 | E4: ='1.2D플랫폼 구축'!K11:K11 -> 1.2266675e+09 | F4: 1단계
C5: 2. 3D플랫폼 구축(제작및관리(CS)포함) | E5: ='3D플랫폼 구축(제작및관리(CS)포함)'!K11 -> 1.4512722e+09 | F5: 1 ~ 2단계
C6: 3. 플랫폼 운영관리 | E6: ='3.플랫폼 운영관리'!K11 -> 4.4587264e+08 | F6: 1~ 2단계
C7: 4. 2D/3D 특화서비스 | E7: ='4.2D 및 3D 특화서비스'!E19:N19 -> 6.8409884e+08 | F7: 2단계
C8: 5. 대국민 서비스 | E8: ='5.대국민서비스'!E19:N19 -> 1.6248368e+08 | F8: 2단계
C9: 6. 데이터 관리체계 | E9: ='6.데이터 관리체계 구축'!K11 -> 7.5353877e+08 | F9: 2단계
B10: DB 표준화 | C10: 7. DB 표준화(투입공수) | E10: ='7.통합DB구축(투입공수)'!G58 -> 526874913 | F10: 1단계
B11: 컨설팅 | C11: 8. 컨설팅(투입공수) | E11: ='8.컨설팅(투입공수)'!H28 -> 1.6318721e+08 | F11: 1단계
B12: 초정밀 3D 데이터 구축 | C12: 9.드론LiDAR구축 | E12: ='9.초정밀3D구축(드론LiDAR)'!AC23 -> 4.1080887e+08 | F12: 1~2단계 (부가세 포함)
B13: 전산자원 | C13: 10.전산자원도입(통합발주) | E13: ='10.전산자원도입(통합발주)'!G10 -> 74000000 | F13: 1단계 (부가세 포함)
B14: 소 계(부가세별도) | E14: =SUM(E4:E11) -> 5.4139958e+09
B15: 부가가치세(10%) | E15: =E14*0.1 -> 5.4139958e+08
B16: 총계 | E16: =TRUNC(SUM(E12:E15), -6) -> 6440000000 | F16: (십만단위 절사) | I16: =E16-H16 -> 6440000000

Sheet 1.2D플랫폼 구축
B1: "산림공간 디지털플랫폼 사업_2D플랫폼" 소프트웨어 개발비 산정
L2: (소프트웨어사업 대가산정 가이드, 2022. KOSA)
B4: ○ 개발원가 산정 | L4: (단위 : 원)
B5: 총기능점수 | D5: 기능점수당 단가 | F5: 보정계수 | K5: 개발원가
F6: 규모 | G6: 연계복잡성 | H6: 성능 | I6: 운영환경 | J6: 보안성
B7: =J30 -> 1541 | D7: 605784 | F7: =K21 -> 0.89602517 | G7: =K22 -> 1 | H7: =K23 -> 1.05 | I7: =K24 -> 1.13 | J7: =K25 -> 1.03 | K7: =PRODUCT(B7:J7) -> 1.0222229e+09
B8: 합계(보정 후 개발원가) | K8: =SUM(K7:L7) -> 1.0222229e+09
B9: 이윤 | J9: 0.2 | K9: =K8*J9 -> 2.0444458e+08
B10: 직접경비 | K10: =K17 -> 0
B11: 소프트웨어 개발비(부가세 별도) | K11: =SUM(K8:L10) -> 1.2266675e+09
B13: ○ 직접경비 | L13: (단위 : 원)
B14: 구분 | D14: 산출내역 | K14: 금액
B17: 합 계 | K17: =SUM(K15:L16) -> 0
B19: ○ 보정계수 산정
B20: 보정계수 구분 | D20: 복잡도 및 난이도 수준 | K20: 보정계수
B21: SW규모 | D21: ="= 0.4057 x (log e("&B7&") - 7.1978)^2 + 0.8878 (단, 500FP 미만 1.28, 3,000FP 초과 1.153 적용)" -> = 0.4057 x (log e(1541) - 7.1978)^2 + 0.8878 (단, 500FP 미만 1.28, 3,000FP 초과 1.153 적용) | K21: =IF(B7<500,1.28,IF(B7>3000,1.153,0.4057*(LN(B7)-7.1978)^2+0.8878)) -> 0.89602517
B22: 연계복잡성 | D22: 3. 3~5개의 타 기관 연계 | K22: =VLOOKUP(D22,N22:O26,2,1) -> 1 | N22: 1. 타 기관 연계 없음 | O22: 0.88
B23: 성능 요구수준 | D23: 4. 응답시간이나 처리율이 모든 업무시간에 중요하며, 처리 시한이 명시되어 있다. | K23: =VLOOKUP(D23,N27:O31,2,1) -> 1.05 | N23: 2. 1~2개의 타 기관 연계 | O23: 0.94
B24: 운영환경 호환성 | D24: 4. 운영환경 호환성에 대한 요구사항이 있으며, 이질적인 하드웨어 및 소프트웨어 환경에서 운영되도록 설계된다. | K24: =VLOOKUP(D24,N32:O36,2,1) -> 1.13 | N24: 3. 3~5개의 타 기관 연계 | O24: 1
B25: 보안성 요구수준 | D25: 3. 3가지 요구사항이 포함되어 있다. | K25: =VLOOKUP(D25,N37:O41,2,1) -> 1.03 | N25: 4. 6~10개의 타 기관 연계 | O25: 1.06
N26: 5. 10개 초과의 타 기관 연계 | O26: 1.12
B27: ○ FP 집계 | N27: 1. 응답성능에 대한 특별한 요구사항이 없다. | O27: 0.91
B28: 구분 | E28: ILF | F28: EIF | G28: EI | H28: EO | I28: EQ | J28: 계 | N28: 2. 응답성능에 대한 요구사항이 있으나 특별한 조치가 필요하지는 않다. | O28: 0.95
B29: 기능수 | E29: =COUNTIF('1-1.FP산정(간이법)'!$F$5:$F9997,"ILF") -> 12 | F29: =COUNTIF('1-1.FP산정(간이법)'!$F$5:$F9997,"EIF") -> 2 | G29: =COUNTIF('1-1.FP산정(간이법)'!$F$5:$F9997,"EI") -> 50 | H29: =COUNTIF('1-1.FP산정(간이법)'!$F$5:$F9997,"EO") -> 183 | I29: =COUNTIF('1-1.FP산정(간이법)'!$F$5:$F9997,"EQ") -> 74 | J29: =SUM(E29:I29) -> 321 | N29: 3. 응답시간이나 처리율이 피크타임(peak time)에 중요하며, 처리 시한이 명시되어 있다. | O29: 1
B30: 기능점수 | E30: =SUMIF('1-1.FP산정(간이법)'!$F$5:$F9997,"ILF",'1-1.FP산정(간이법)'!$G$5:$G9997) -> 90 | F30: =SUMIF('1-1.FP산정(간이법)'!$F$5:$F9997,"EIF",'1-1.FP산정(간이법)'!$G$5:$G9997) -> 10.8 | G30: =SUMIF('1-1.FP산정(간이법)'!$F$5:$F9997,"EI",'1-1.FP산정(간이법)'!$G$5:$G9997) -> 200 | H30: =SUMIF('1-1.FP산정(간이법)'!$F$5:$F9997,"EO",'1-1.FP산정(간이법)'!$G$5:$G9997) -> 951.6 | I30: =SUMIF('1-1.FP산정(간이법)'!$F$5:$F9997,"EQ",'1-1.FP산정(간이법)'!$G$5:$G9997) -> 288.6 | J30: =SUM(E30:I30) -> 1541 | N30: 4. 응답시간이나 처리율이 모든 업무시간에 중요하며, 처리 시한이 명시되어 있다. | O30: 1.05
B31: 비중 | E31: =IF($J$30>0,E30/$J$30,"-") -> 0.058403634 | F31: =IF($J$30>0,F30/$J$30,"-") -> 0.0070084361 | G31: =IF($J$30>0,G30/$J$30,"-") -> 0.12978585 | H31: =IF($J$30>0,H30/$J$30,"-") -> 0.61752109 | I31: =IF($J$30>0,I30/$J$30,"-") -> 0.18728099 | J31: =SUM(E31:I31) -> 1 | N31: 5. 응답성능 요구수준이 엄격하여, 설계, 개발 또는 구현 단계에서 성능 분석도구 사용이 필요하다. | O31: 1.09
N32: 1. 운영환경 호환성에 대한 요구사항이 없다. | O32: 0.94
N33: 2. 운영환경 호환성에 대한 요구사항이 있으며, 동일 하드웨어 및 소프트웨어 환경에서 운영되도록 설계된다. | O33: 1
N34: 3. 운영환경 호환성에 대한 요구사항이 있으며, 유사 하드웨어 및 소프트웨어 환경에서 운영되도록 설계된다. | O34: 1.06
N35: 4. 운영환경 호환성에 대한 요구사항이 있으며, 이질적인 하드웨어 및 소프트웨어 환경에서 운영되도록 설계된다. | O35: 1.13
N36: 5. 항목 4에 더하여 일반적 산출물 이외에 장소에서 원활한 운영을 보장하기 위한 운영 절차의 문서화와 사전 모의훈련이 요구된다. | O36: 1.19
N37: 1. 암호화, 웹취약점 점검, 시큐어코딩, 개인정보보호 등 1가지 보안 요구사항이 포함되어 있다. | O37: 0.97
N38: 2. 2가지 요구사항이 포함되어 있다. | O38: 1
N39: 3. 3가지 요구사항이 포함되어 있다. | O39: 1.03
N40: 4. 4가지 항목이 모두 포함되어 있다. | O40: 1.06
N41: 5. 5가지 이상의 보안 요구사항이 포함되어 있다. | O41: 1.08

Sheet 1-1.FP산정(간이법)
B1: 기능점수 산정 (간이법)
B3: 기능명 | F3: 데이터 및 트랜잭션 기능 | G3: FP 산출 | H3: 비고 | I3: 제안요청서 v1.6
B4: ①어플리케이션명 | C4: ②세부 업무명 | D4: ③단위프로세스명 | E4: 단위프로세스 설명 | F4: ④FP유형 | G4: ⑤가중치 | I4: 변경
A5: 2D | B5: GIS프레임워크(REST API) | C5: 데이터요약분석 API | D5: 포인트 집계 | E5: 포인트 집계 | F5: EO | G5: =IF(F5="","",IF(F5="EI",4,IF(F5="EO",5.2,IF(F5="EQ",3.9,IF(F5="ILF",7.5,IF(F5="EIF",5.4)))))) -> 5.2 | H5: SFR-003 | I5: SFR-003
B6: GIS프레임워크(REST API) | C6: 데이터요약분석 API | D6: 공간조인 | E6: 공간조인 | F6: EO | G6: =IF(F6="","",IF(F6="EI",4,IF(F6="EO",5.2,IF(F6="EQ",3.9,IF(F6="ILF",7.5,IF(F6="EIF",5.4)))))) -> 5.2 | H6: SFR-003 | I6: SFR-003
B7: GIS프레임워크(REST API) | C7: 데이터요약분석 API | D7: 주변 집계 | E7: 주변 집계 | F7: EO | G7: =IF(F7="","",IF(F7="EI",4,IF(F7="EO",5.2,IF(F7="EQ",3.9,IF(F7="ILF",7.5,IF(F7="EIF",5.4)))))) -> 5.2 | H7: SFR-003 | I7: SFR-003
B8: GIS프레임워크(REST API) | C8: 데이터요약분석 API | D8: 영역 내 집계 | E8: 영역 내 집계 | F8: EO | G8: =IF(F8="","",IF(F8="EI",4,IF(F8="EO",5.2,IF(F8="EQ",3.9,IF(F8="ILF",7.5,IF(F8="EIF",5.4)))))) -> 5.2 | H8: SFR-003 | I8: SFR-003
B9: GIS프레임워크(REST API) | C9: 데이터요약분석 API | D9: 공간 분포 | E9: 공간 분포 | F9: EO | G9: =IF(F9="","",IF(F9="EI",4,IF(F9="EO",5.2,IF(F9="EQ",3.9,IF(F9="ILF",7.5,IF(F9="EIF",5.4)))))) -> 5.2 | H9: SFR-003 | I9: SFR-003
B10: GIS프레임워크(REST API) | C10: 위치찾기분석 API | D10: 공간 조건 검색 | E10: 공간 조건 검색 | F10: EO | G10: =IF(F10="","",IF(F10="EI",4,IF(F10="EO",5.2,IF(F10="EQ",3.9,IF(F10="ILF",7.5,IF(F10="EIF",5.4)))))) -> 5.2 | H10: SFR-003 | I10: SFR-003
B11: GIS프레임워크(REST API) | C11: 위치찾기분석 API | D11: 공간 조건 추출 | E11: 공간 조건 추출 | F11: EO | G11: =IF(F11="","",IF(F11="EI",4,IF(F11="EO",5.2,IF(F11="EQ",3.9,IF(F11="ILF",7.5,IF(F11="EIF",5.4)))))) -> 5.2 | H11: SFR-003 | I11: SFR-003
B12: GIS프레임워크(REST API) | C12: 위치찾기분석 API | D12: 중심 찾기 실행 | E12: 중심 찾기 실행 | F12: EO | G12: =IF(F12="","",IF(F12="EI",4,IF(F12="EO",5.2,IF(F12="EQ",3.9,IF(F12="ILF",7.5,IF(F12="EIF",5.4)))))) -> 5.2 | H12: SFR-003 | I12: SFR-003
B13: GIS프레임워크(REST API) | C13: 위치찾기분석 API | D13: 유사한 위치 찾기 실행 | E13: 유사한 위치 찾기 실행 | F13: EO | G13: =IF(F13="","",IF(F13="EI",4,IF(F13="EO",5.2,IF(F13="EQ",3.9,IF(F13="ILF",7.5,IF(F13="EIF",5.4)))))) -> 5.2 | H13: SFR-003 | I13: SFR-003
B14: GIS프레임워크(REST API) | C14: 공간패턴 분석 API | D14: 밀도 계산 | E14: 밀도 계산 | F14: EO | G14: =IF(F14="","",IF(F14="EI",4,IF(F14="EO",5.2,IF(F14="EQ",3.9,IF(F14="ILF",7.5,IF(F14="EIF",5.4)))))) -> 5.2 | H14: SFR-003 | I14: SFR-003
B15: GIS프레임워크(REST API) | C15: 공간패턴 분석 API | D15: 핫 스팟 | E15: 핫 스팟 | F15: EO | G15: =IF(F15="","",IF(F15="EI",4,IF(F15="EO",5.2,IF(F15="EQ",3.9,IF(F15="ILF",7.5,IF(F15="EIF",5.4)))))) -> 5.2 | H15: SFR-003 | I15: SFR-003
B16: GIS프레임워크(REST API) | C16: 공간패턴 분석 API | D16: 포인트 군집 | E16: 포인트 군집 | F16: EO | G16: =IF(F16="","",IF(F16="EI",4,IF(F16="EO",5.2,IF(F16="EQ",3.9,IF(F16="ILF",7.5,IF(F16="EIF",5.4)))))) -> 5.2 | H16: SFR-003 | I16: SFR-003
B17: GIS프레임워크(REST API) | C17: 공간패턴 분석 API | D17: 포인트 내삽 찾기 | E17: 포인트 내삽 찾기 | F17: EO | G17: =IF(F17="","",IF(F17="EI",4,IF(F17="EO",5.2,IF(F17="EQ",3.9,IF(F17="ILF",7.5,IF(F17="EIF",5.4)))))) -> 5.2 | H17: SFR-003 | I17: SFR-003
... B53: GIS프레임워크(REST API) | C53: 위치검색 | D53: 경위도좌표 위치검색 | E53: 경위도좌표 위치검색 | F53: EQ | G53: =IF(F53="","",IF(F53="EI",4,IF(F53="EO",5.2,IF(F53="EQ",3.9,IF(F53="ILF",7.5,IF(F53="EIF",5.4)))))) -> 3.9 | H53: SFR-004 | I53: SFR-005
B54: GIS프레임워크(REST API) | C54: 저장소 관리 | D54: 저장소 정보 | F54: ILF | G54: =IF(F54="","",IF(F54="EI",4,IF(F54="EO",5.2,IF(F54="EQ",3.9,IF(F54="ILF",7.5,IF(F54="EIF",5.4)))))) -> 7.5 | H54: SFR-007 | I54: SFR-009
B55: GIS프레임워크(REST API) | C55: 저장소 관리 | D55: 저장소 목록 조회 | F55: EQ | G55: =IF(F55="","",IF(F55="EI",4,IF(F55="EO",5.2,IF(F55="EQ",3.9,IF(F55="ILF",7.5,IF(F55="EIF",5.4)))))) -> 3.9 | H55: SFR-007 | I55: SFR-009
B56: GIS프레임워크(REST API) | C56: 저장소 관리 | D56: 저장소 상세 조회 | F56: EQ | G56: =IF(F56="","",IF(F56="EI",4,IF(F56="EO",5.2,IF(F56="EQ",3.9,IF(F56="ILF",7.5,IF(F56="EIF",5.4)))))) -> 3.9 | H56: SFR-007 | I56: SFR-009
B57: GIS프레임워크(REST API) | C57: 저장소 관리 | D57: 저장소 등록 | F57: EI | G57: =IF(F57="","",IF(F57="EI",4,IF(F57="EO",5.2,IF(F57="EQ",3.9,IF(F57="ILF",7.5,IF(F57="EIF",5.4)))))) -> 4 | H57: SFR-007 | I57: SFR-009
B58: GIS프레임워크(REST API) | C58: 저장소 관리 | D58: 저장소 수정 | F58: EI | G58: =IF(F58="","",IF(F58="EI",4,IF(F58="EO",5.2,IF(F58="EQ",3.9,IF(F58="ILF",7.5,IF(F58="EIF",5.4)))))) -> 4 | H58: SFR-007 | I58: SFR-009
B59: GIS프레임워크(REST API) | C59: 저장소 관리 | D59: 저장소 삭제 | F59: EI | G59: =IF(F59="","",IF(F59="EI",4,IF(F59="EO",5.2,IF(F59="EQ",3.9,IF(F59="ILF",7.5,IF(F59="EIF",5.4)))))) -> 4 | H59: SFR-007 | I59: SFR-009
B60: GIS프레임워크(REST API) | C60: 사용자 데이터 업로드 | D60: Dxf 파일 서비스 발행 | E60: Dxf 파일 서비스 발행 | F60: EO | G60: =IF(F60="","",IF(F60="EI",4,IF(F60="EO",5.2,IF(F60="EQ",3.9,IF(F60="ILF",7.5,IF(F60="EIF",5.4)))))) -> 5.2 | H60: SFR-005 | I60: SFR-004
B61: GIS프레임워크(REST API) | C61: 사용자 데이터 업로드 | D61: Dxf 파일 업로드 | E61: Dxf 파일 업로드 | F61: EO | G61: =IF(F61="","",IF(F61="EI",4,IF(F61="EO",5.2,IF(F61="EQ",3.9,IF(F61="ILF",7.5,IF(F61="EIF",5.4)))))) -> 5.2 | H61: SFR-005 | I61: SFR-004
B62: GIS프레임워크(REST API) | C62: 사용자 데이터 업로드 | D62: GeoJSON 파일 서비스 발행 | E62: GeoJSON 파일 서비스 발행 | F62: EO | G62: =IF(F62="","",IF(F62="EI",4,IF(F62="EO",5.2,IF(F62="EQ",3.9,IF(F62="ILF",7.5,IF(F62="EIF",5.4)))))) -> 5.2 | H62: SFR-005 | I62: SFR-004
B63: GIS프레임워크(REST API) | C63: 사용자 데이터 업로드 | D63: GeoJSON 파일 업로드 | E63: GeoJSON 파일 업로드 | F63: EO | G63: =IF(F63="","",IF(F63="EI",4,IF(F63="EO",5.2,IF(F63="EQ",3.9,IF(F63="ILF",7.5,IF(F63="EIF",5.4)))))) -> 5.2 | H63: SFR-005 | I63: SFR-004
B64: GIS프레임워크(REST API) | C64: 사용자 데이터 업로드 | D64: GeoJSON 텍스트 서비스 발행 | E64: GeoJSON 텍스트 서비스 발행 | F64: EO | G64: =IF(F64="","",IF(F64="EI",4,IF(F64="EO",5.2,IF(F64="EQ",3.9,IF(F64="ILF",7.5,IF(F64="EIF",5.4)))))) -> 5.2 | H64: SFR-005 | I64: SFR-004
B65: GIS프레임워크(REST API) | C65: 사용자 데이터 업로드 | D65: Shape 파일 서비스 발행 | E65: Shape 파일 서비스 발행 | F65: EO | G65: =IF(F65="","",IF(F65="EI",4,IF(F65="EO",5.2,IF(F65="EQ",3.9,IF(F65="ILF",7.5,IF(F65="EIF",5.4)))))) -> 5.2 | H65: SFR-005 | I65: SFR-004
B66: GIS프레임워크(REST API) | C66: 사용자 데이터 업로드 | D66: Shape 파일 업로드 | E66: Shape 파일 업로드 | F66: EO | G66: =IF(F66="","",IF(F66="EI",4,IF(F66="EO",5.2,IF(F66="EQ",3.9,IF(F66="ILF",7.5,IF(F66="EIF",5.4)))))) -> 5.2 | H66: SFR-005 | I66: SFR-004
B67: GIS프레임워크(REST API) | C67: 사용자 데이터 업로드 | D67: GeoTiff 파일 서비스 발행 | E67: GeoTiff 파일 서비스 발행 | F67: EO | G67: =IF(F67="","",IF(F67="EI",4,IF(F67="EO",5.2,IF(F67="EQ",3.9,IF(F67="ILF",7.5,IF(F67="EIF",5.4)))))) -> 5.2 | H67: SFR-005 | I67: SFR-004
B68: GIS프레임워크(REST API) | C68: 사용자 데이터 업로드 | D68: GeoTiff 파일 업로드 | E68: GeoTiff 파일 업로드 | F68: EO | G68: =IF(F68="","",IF(F68="EI",4,IF(F68="EO",5.2,IF(F68="EQ",3.9,IF(F68="ILF",7.5,IF(F68="EIF",5.4)))))) -> 5.2 | H68: SFR-005 | I68: SFR-004
B69: GIS프레임워크(REST API) | C69: 사용자 데이터 업로드 | D69: 이미지 레이어 업로드 | E69: 이미지 레이어 업로드 | F69: EO | G69: =IF(F69="","",IF(F69="EI",4,IF(F69="EO",5.2,IF(F69="EQ",3.9,IF(F69="ILF",7.5,IF(F69="EIF",5.4)))))) -> 5.2 | H69: SFR-005 | I69: SFR-004
B70: GIS프레임워크(REST API) | C70: 레이어 정보 관리 | D70: 레이어 정보 | E70: 레이어 정보 | F70: ILF | G70: =IF(F70="","",IF(F70="EI",4,IF(F70="EO",5.2,IF(F70="EQ",3.9,IF(F70="ILF",7.5,IF(F70="EIF",5.4)))))) -> 7.5 | H70: SFR-005 | I70: SFR-006
B71: GIS프레임워크(REST API) | C71: 레이어 정보 관리 | D71: 레이어 정보 목록조회 | E71: 레이어 정보 리스트 | F71: EQ | G71: =IF(F71="","",IF(F71="EI",4,IF(F71="EO",5.2,IF(F71="EQ",3.9,IF(F71="ILF",7.5,IF(F71="EIF",5.4)))))) -> 3.9 | H71: SFR-005 | I71: SFR-006
... B193: 저작도구(javascript API) | C193: 지도 Javascript SDK | D193: 지도 줌 설정클래스 | E193: 지도 줌 설정클래스 | F193: EQ | G193: =IF(F193="","",IF(F193="EI",4,IF(F193="EO",5.2,IF(F193="EQ",3.9,IF(F193="ILF",7.5,IF(F193="EIF",5.4)))))) -> 3.9 | H193: SFR-008 | I193: SFR-009
B194: 개발자센터(지도예제) | C194: 지도제어 | D194: 지도생성 | E194: 지도생성 | F194: EO | G194: =IF(F194="","",IF(F194="EI",4,IF(F194="EO",5.2,IF(F194="EQ",3.9,IF(F194="ILF",7.5,IF(F194="EIF",5.4)))))) -> 5.2 | H194: SFR-009
B195: 개발자센터(지도예제) | C195: 지도제어 | D195: 배경지도설정 | E195: 배경지도설정 | F195: EO | G195: =IF(F195="","",IF(F195="EI",4,IF(F195="EO",5.2,IF(F195="EQ",3.9,IF(F195="ILF",7.5,IF(F195="EIF",5.4)))))) -> 5.2 | H195: SFR-009
B196: 개발자센터(지도예제) | C196: 지도제어 | D196: 배경지도 최적화 | E196: 배경지도 최적화 | F196: EO | G196: =IF(F196="","",IF(F196="EI",4,IF(F196="EO",5.2,IF(F196="EQ",3.9,IF(F196="ILF",7.5,IF(F196="EIF",5.4)))))) -> 5.2 | H196: SFR-009
B197: 개발자센터(지도예제) | C197: 지도제어 | D197: 사용자 지정 배경지도 | E197: 사용자 지정 배경지도 | F197: EO | G197: =IF(F197="","",IF(F197="EI",4,IF(F197="EO",5.2,IF(F197="EQ",3.9,IF(F197="ILF",7.5,IF(F197="EIF",5.4)))))) -> 5.2 | H197: SFR-009
...

Sheet 3D플랫폼 구축(제작및관리(CS)포함)
B1: "산림공간 디지털플랫폼 사업_3D플랫폼 제작 및 관리도구" 소프트웨어 개발비 산정
L2: (소프트웨어사업 대가산정 가이드, 2022. KOSA)
B4: ○ 개발원가 산정 | L4: (단위 : 원)
B5: 총기능점수 | D5: 기능점수당 단가 | F5: 보정계수 | K5: 개발원가
F6: 규모 | G6: 연계복잡성 | H6: 성능 | I6: 운영환경 | J6: 보안성
B7: =J30 -> 1774.8 | D7: 605784 | F7: =K21 -> 0.92043993 | G7: =K22 -> 1 | H7: =K23 -> 1.05 | I7: =K24 -> 1.13 | J7: =K25 -> 1.03 | K7: =PRODUCT(B7:J7) -> 1.2093935e+09
B8: 합계(보정 후 개발원가) | K8: =SUM(K7:L7) -> 1.2093935e+09
B9: 이윤 | J9: 0.2 | K9: =K8*J9 -> 2.418787e+08
B10: 직접경비 | K10: =K17 -> 0
B11: 소프트웨어 개발비(부가세 별도) | K11: =SUM(K8:L10) -> 1.4512722e+09
B13: ○ 직접경비 | L13: (단위 : 원)
B14: 구분 | D14: 산출내역 | K14: 금액
B17: 합 계 | K17: =SUM(K15:L16) -> 0
B19: ○ 보정계수 산정
B20: 보정계수 구분 | D20: 복잡도 및 난이도 수준 | K20: 보정계수
B21: SW규모 | D21: ="= 0.4057 x (log e("&B7&") - 7.1978)^2 + 0.8878 (단, 500FP 미만 1.28, 3,000FP 초과 1.153 적용)" -> = 0.4057 x (log e(1774.8) - 7.1978)^2 + 0.8878 (단, 500FP 미만 1.28, 3,000FP 초과 1.153 적용) | K21: =IF(B7<500,1.28,IF(B7>3000,1.153,0.4057*(LN(B7)-7.1978)^2+0.8878)) -> 0.92043993
B22: 연계복잡성 | D22: 3. 3~5개의 타 기관 연계 | K22: =VLOOKUP(D22,N22:O26,2,1) -> 1 | N22: 1. 타 기관 연계 없음 | O22: 0.88
B23: 성능 요구수준 | D23: 4. 응답시간이나 처리율이 모든 업무시간에 중요하며, 처리 시한이 명시되어 있다. | K23: =VLOOKUP(D23,N27:O31,2,1) -> 1.05 | N23: 2. 1~2개의 타 기관 연계 | O23: 0.94
B24: 운영환경 호환성 | D24: 4. 운영환경 호환성에 대한 요구사항이 있으며, 이질적인 하드웨어 및 소프트웨어 환경에서 운영되도록 설계된다. | K24: =VLOOKUP(D24,N32:O36,2,1) -> 1.13 | N24: 3. 3~5개의 타 기관 연계 | O24: 1
B25: 보안성 요구수준 | D25: 3. 3가지 요구사항이 포함되어 있다. | K25: =VLOOKUP(D25,N37:O41,2,1) -> 1.03 | N25: 4. 6~10개의 타 기관 연계 | O25: 1.06
N26: 5. 10개 초과의 타 기관 연계 | O26: 1.12
B27: ○ FP 집계 | N27: 1. 응답성능에 대한 특별한 요구사항이 없다. | O27: 0.91
B28: 구분 | E28: ILF | F28: EIF | G28: EI | H28: EO | I28: EQ | J28: 계 | N28: 2. 응답성능에 대한 요구사항이 있으나 특별한 조치가 필요하지는 않다. | O28: 0.95
B29: 기능수 | E29: =COUNTIF('2-1.FP산정(간이법)'!$F$5:$F10634,"ILF") -> 21 | F29: =COUNTIF('2-1.FP산정(간이법)'!$F$5:$F10634,"EIF") -> 6 | G29: =COUNTIF('2-1.FP산정(간이법)'!$F$5:$F10634,"EI") -> 106 | H29: =COUNTIF('2-1.FP산정(간이법)'!$F$5:$F10634,"EO") -> 206 | I29: =COUNTIF('2-1.FP산정(간이법)'!$F$5:$F10634,"EQ") -> 23 | J29: =SUM(E29:I29) -> 362 | N29: 3. 응답시간이나 처리율이 피크타임(peak time)에 중요하며, 처리 시한이 명시되어 있다. | O29: 1
B30: 기능점수 | E30: =SUMIF('2-1.FP산정(간이법)'!$F$5:$F10634,"ILF",'2-1.FP산정(간이법)'!$G$5:$G10634) -> 157.5 | F30: =SUMIF('2-1.FP산정(간이법)'!$F$5:$F10634,"EIF",'2-1.FP산정(간이법)'!$G$5:$G10634) -> 32.4 | G30: =SUMIF('2-1.FP산정(간이법)'!$F$5:$F10634,"EI",'2-1.FP산정(간이법)'!$G$5:$G10634) -> 424 | H30: =SUMIF('2-1.FP산정(간이법)'!$F$5:$F10634,"EO",'2-1.FP산정(간이법)'!$G$5:$G10634) -> 1071.2 | I30: =SUMIF('2-1.FP산정(간이법)'!$F$5:$F10634,"EQ",'2-1.FP산정(간이법)'!$G$5:$G10634) -> 89.7 | J30: =SUM(E30:I30) -> 1774.8 | N30: 4. 응답시간이나 처리율이 모든 업무시간에 중요하며, 처리 시한이 명시되어 있다. | O30: 1.05
B31: 비중 | E31: =IF($J$30>0,E30/$J$30,"-") -> 0.088742394 | F31: =IF($J$30>0,F30/$J$30,"-") -> 0.018255578 | G31: =IF($J$30>0,G30/$J$30,"-") -> 0.23890016 | H31: =IF($J$30>0,H30/$J$30,"-") -> 0.60356096 | I31: =IF($J$30>0,I30/$J$30,"-") -> 0.050540906 | J31: =SUM(E31:I31) -> 1 | N31: 5. 응답성능 요구수준이 엄격하여, 설계, 개발 또는 구현 단계에서 성능 분석도구 사용이 필요하다. | O31: 1.09
N32: 1. 운영환경 호환성에 대한 요구사항이 없다. | O32: 0.94
N33: 2. 운영환경 호환성에 대한 요구사항이 있으며, 동일 하드웨어 및 소프트웨어 환경에서 운영되도록 설계된다. | O33: 1
N34: 3. 운영환경 호환성에 대한 요구사항이 있으며, 유사 하드웨어 및 소프트웨어 환경에서 운영되도록 설계된다. | O34: 1.06
N35: 4. 운영환경 호환성에 대한 요구사항이 있으며, 이질적인 하드웨어 및 소프트웨어 환경에서 운영되도록 설계된다. | O35: 1.13
N36: 5. 항목 4에 더하여 일반적 산출물 이외에 장소에서 원활한 운영을 보장하기 위한 운영 절차의 문서화와 사전 모의훈련이 요구된다. | O36: 1.19
N37: 1. 암호화, 웹취약점 점검, 시큐어코딩, 개인정보보호 등 1가지 보안 요구사항이 포함되어 있다. | O37: 0.97
N38: 2. 2가지 요구사항이 포함되어 있다. | O38: 1
N39: 3. 3가지 요구사항이 포함되어 있다. | O39: 1.03
N40: 4. 4가지 항목이 모두 포함되어 있다. | O40: 1.06
N41: 5. 5가지 이상의 보안 요구사항이 포함되어 있다. | O41: 1.08

Sheet 2-1.FP산정(간이법)
B1: 기능점수 산정 (간이법)
B3: 기능명 | F3: 데이터 및 트랜잭션 기능 | G3: FP 산출 | H3: 비고
B4: ①어플리케이션명 | C4: ②세부 업무명 | D4: ③단위프로세스명 | E4: 단위프로세스 설명 | F4: ④FP유형 | G4: ⑤가중치
B5: □ 디지털트윈 3D 제작 도구 개발 | G5: =IF(F5="","",IF(F5="EI",4,IF(F5="EO",5.2,IF(F5="EQ",3.9,IF(F5="ILF",7.5,IF(F5="EIF",5.4))))))
B6: 배경지도 표출 | C6: 국토부 DB 반영 | D6: K-GEO, V-World 연계 서비스 혹은 자료 수령 후 반영 | F6: EIF | G6: =IF(F6="","",IF(F6="EI",4,IF(F6="EO",5.2,IF(F6="EQ",3.9,IF(F6="ILF",7.5,IF(F6="EIF",5.4)))))) -> 5.4
C7: 벡터지도 연계 | D7: 국토부 벡터지도 연계 | F7: EIF | G7: =IF(F7="","",IF(F7="EI",4,IF(F7="EO",5.2,IF(F7="EQ",3.9,IF(F7="ILF",7.5,IF(F7="EIF",5.4)))))) -> 5.4
C8: 항공영상지도 연계 | D8: 국토부 항공영상지도 연계 | F8: EIF | G8: =IF(F8="","",IF(F8="EI",4,IF(F8="EO",5.2,IF(F8="EQ",3.9,IF(F8="ILF",7.5,IF(F8="EIF",5.4)))))) -> 5.4
C9: 위성영상지도 연계 | D9: 국토부 위성영상지도 연계 | F9: EIF | G9: =IF(F9="","",IF(F9="EI",4,IF(F9="EO",5.2,IF(F9="EQ",3.9,IF(F9="ILF",7.5,IF(F9="EIF",5.4)))))) -> 5.4
C10: 바로e맵 연계 | D10: 바로e맵 배경지도 매쉬업 연계 | F10: EIF | G10: =IF(F10="","",IF(F10="EI",4,IF(F10="EO",5.2,IF(F10="EQ",3.9,IF(F10="ILF",7.5,IF(F10="EIF",5.4)))))) -> 5.4
B11: 메인화면 | C11: 메인화면 구성 | D11: 일반 관리 화면 모드 및 대시보드 화면 모드 전환 기능 | F11: EO | G11: =IF(F11="","",IF(F11="EI",4,IF(F11="EO",5.2,IF(F11="EQ",3.9,IF(F11="ILF",7.5,IF(F11="EIF",5.4)))))) -> 5.2
C12: 좌표정보 | D12: 해당 지점의 경위도 및 높이 정보 제공 | F12: EO | G12: =IF(F12="","",IF(F12="EI",4,IF(F12="EO",5.2,IF(F12="EQ",3.9,IF(F12="ILF",7.5,IF(F12="EIF",5.4)))))) -> 5.2
C13: 날자정보 | D13: 해당 지점의 날자정보 제공 | F13: EO | G13: =IF(F13="","",IF(F13="EI",4,IF(F13="EO",5.2,IF(F13="EQ",3.9,IF(F13="ILF",7.5,IF(F13="EIF",5.4)))))) -> 5.2
C14: 시간정보 | D14: 해당 지점의 시간정보 제공 | F14: EO | G14: =IF(F14="","",IF(F14="EI",4,IF(F14="EO",5.2,IF(F14="EQ",3.9,IF(F14="ILF",7.5,IF(F14="EIF",5.4)))))) -> 5.2
C15: 기상정보 | D15: 해당 지점의 기상정보 제공 | F15: EIF | G15: =IF(F15="","",IF(F15="EI",4,IF(F15="EO",5.2,IF(F15="EQ",3.9,IF(F15="ILF",7.5,IF(F15="EIF",5.4)))))) -> 5.4
B16: 3차원 지도제어 | C16: 확대/축소/이동 | D16: 지도화면 영역 확대, 축소, 이동, 초기화(위치, 선택), 정북방향, 현재위치설정 | F16: EO | G16: =IF(F16="","",IF(F16="EI",4,IF(F16="EO",5.2,IF(F16="EQ",3.9,IF(F16="ILF",7.5,IF(F16="EIF",5.4)))))) -> 5.2
C17: 2D/3D 지도 모드 설정 | D17: 기본 3차원으로 지도 제공하며, 사용자 2D지도 선택시 Top-View 방식으로 전환 | F17: EO | G17: =IF(F17="","",IF(F17="EI",4,IF(F17="EO",5.2,IF(F17="EQ",3.9,IF(F17="ILF",7.5,IF(F17="EIF",5.4)))))) -> 5.2
C18: 국가지점번호 | D18: 위도/경도, 국가지점번호로 위치등록 | F18: EI | G18: =IF(F18="","",IF(F18="EI",4,IF(F18="EO",5.2,IF(F18="EQ",3.9,IF(F18="ILF",7.5,IF(F18="EIF",5.4)))))) -> 4
C19: 이미지 저장 | D19: 현재 화면에 보이는 지도 이미지 저장 | F19: EO | G19: =IF(F19="","",IF(F19="EI",4,IF(F19="EO",5.2,IF(F19="EQ",3.9,IF(F19="ILF",7.5,IF(F19="EIF",5.4)))))) -> 5.2
C20: 메모기능 | D20: 지도상의 메모 작성기능 | F20: EO | G20: =IF(F20="","",IF(F20="EI",4,IF(F20="EO",5.2,IF(F20="EQ",3.9,IF(F20="ILF",7.5,IF(F20="EIF",5.4)))))) -> 5.2
C21: 지도 인쇄 | D21: 지도화면 인쇄 | F21: EO | G21: =IF(F21="","",IF(F21="EI",4,IF(F21="EO",5.2,IF(F21="EQ",3.9,IF(F21="ILF",7.5,IF(F21="EIF",5.4)))))) -> 5.2
B22: 통합 검색 | C22: 공간정보 지도 검색(주소) | D22: 주소를 입력하여 해당 위치로 지도 이동 | F22: EO | G22: =IF(F22="","",IF(F22="EI",4,IF(F22="EO",5.2,IF(F22="EQ",3.9,IF(F22="ILF",7.5,IF(F22="EIF",5.4)))))) -> 5.2
C23: 공간정보 지도 검색(명칭) | D23: 시설물 이름을 입력하여 해당 위치로 지도 이동 | F23: EO | G23: =IF(F23="","",IF(F23="EI",4,IF(F23="EO",5.2,IF(F23="EQ",3.9,IF(F23="ILF",7.5,IF(F23="EIF",5.4)))))) -> 5.2
C24: 공간정보 지도 검색(데이터) | D24: 데이터 이름을 입력하여 해당 위치로 지도 이동 | F24: EO | G24: =IF(F24="","",IF(F24="EI",4,IF(F24="EO",5.2,IF(F24="EQ",3.9,IF(F24="ILF",7.5,IF(F24="EIF",5.4)))))) -> 5.2
C25: 공간정보 지도 검색(통합검색) | D25: 주소, 좌표, 명칭 등 통합적 검색 및 해당 위치로 지도 이동 | F25: EO | G25: =IF(F25="","",IF(F25="EI",4,IF(F25="EO",5.2,IF(F25="EQ",3.9,IF(F25="ILF",7.5,IF(F25="EIF",5.4)))))) -> 5.2
B26: 측정기능 | C26: 높이측정 | D26: 지도의 지형 또는 건물의 높이 측정 | F26: EO | G26: =IF(F26="","",IF(F26="EI",4,IF(F26="EO",5.2,IF(F26="EQ",3.9,IF(F26="ILF",7.5,IF(F26="EIF",5.4)))))) -> 5.2
C27: 면적측정 | D27: 지도의 지형 면적 측정 | F27: EO | G27: =IF(F27="","",IF(F27="EI",4,IF(F27="EO",5.2,IF(F27="EQ",3.9,IF(F27="ILF",7.5,IF(F27="EIF",5.4)))))) -> 5.2
C28: 거리측정 | D28: 지도의 지형 거리 측정 | F28: EO | G28: =IF(F28="","",IF(F28="EI",4,IF(F28="EO",5.2,IF(F28="EQ",3.9,IF(F28="ILF",7.5,IF(F28="EIF",5.4)))))) -> 5.2
D29: 지점간 거리 및 누적거리 측정 | F29: EO | G29: =IF(F29="","",IF(F29="EI",4,IF(F29="EO",5.2,IF(F29="EQ",3.9,IF(F29="ILF",7.5,IF(F29="EIF",5.4)))))) -> 5.2
C30: 각도측정 | D30: 지도의 지형 각도 측정 | F30: EO | G30: =IF(F30="","",IF(F30="EI",4,IF(F30="EO",5.2,IF(F30="EQ",3.9,IF(F30="ILF",7.5,IF(F30="EIF",5.4)))))) -> 5.2
B31: 분석기능 | C31: 일조권 시간 설정 | D31: 3차원 지도 일조권 시간 설정 | F31: EI | G31: =IF(F31="","",IF(F31="EI",4,IF(F31="EO",5.2,IF(F31="EQ",3.9,IF(F31="ILF",7.5,IF(F31="EIF",5.4)))))) -> 4
C32: 일조권 계절 설정 | D32: 3차원 지도 일조권 계절 설정 | F32: EI | G32: =IF(F32="","",IF(F32="EI",4,IF(F32="EO",5.2,IF(F32="EQ",3.9,IF(F32="ILF",7.5,IF(F32="EIF",5.4)))))) -> 4
C33: 일조권 분석 | D33: 3차원 지도 일조권 분석 | F33: EO | G33: =IF(F33="","",IF(F33="EI",4,IF(F33="EO",5.2,IF(F33="EQ",3.9,IF(F33="ILF",7.5,IF(F33="EIF",5.4)))))) -> 5.2
C34: 일조권 배속 설정 | D34: 3차원 지도 일조권 배속 설정 | F34: EI | G34: =IF(F34="","",IF(F34="EI",4,IF(F34="EO",5.2,IF(F34="EQ",3.9,IF(F34="ILF",7.5,IF(F34="EIF",5.4)))))) -> 4
C35: 일조권 자동 실행 | D35: 3차원 지도 일조권 자동 실행 | F35: EO | G35: =IF(F35="","",IF(F35="EI",4,IF(F35="EO",5.2,IF(F35="EQ",3.9,IF(F35="ILF",7.5,IF(F35="EIF",5.4)))))) -> 5.2
C36: 시스템 시간 설정 | D36: 디지털트윈 상의 시스템 시간 설정 | F36: EI | G36: =IF(F36="","",IF(F36="EI",4,IF(F36="EO",5.2,IF(F36="EQ",3.9,IF(F36="ILF",7.5,IF(F36="EIF",5.4)))))) -> 4
C37: 설정 시간 확인 | D37: 디지털트윈 상의 설정 시간 확인 | F37: EQ | G37: =IF(F37="","",IF(F37="EI",4,IF(F37="EO",5.2,IF(F37="EQ",3.9,IF(F37="ILF",7.5,IF(F37="EIF",5.4)))))) -> 3.9
C38: 토공량 분석 | D38: 지도의 지형 토공량 측정 | F38: EO | G38: =IF(F38="","",IF(F38="EI",4,IF(F38="EO",5.2,IF(F38="EQ",3.9,IF(F38="ILF",7.5,IF(F38="EIF",5.4)))))) -> 5.2
C39: 단면도 분석 | D39: 3차원 오브젝트 단면도 분석 | F39: EO | G39: =IF(F39="","",IF(F39="EI",4,IF(F39="EO",5.2,IF(F39="EQ",3.9,IF(F39="ILF",7.5,IF(F39="EIF",5.4)))))) -> 5.2
C40: 경사도 분석 | D40: 지도의 지형 경사도 분석 | F40: EO | G40: =IF(F40="","",IF(F40="EI",4,IF(F40="EO",5.2,IF(F40="EQ",3.9,IF(F40="ILF",7.5,IF(F40="EIF",5.4)))))) -> 5.2
B41: 객체 가시화 | C41: 텍스쳐 모드 | D41: 외부 이미지가 랜더링된 모델 형태의 서비스 | F41: EO | G41: =IF(F41="","",IF(F41="EI",4,IF(F41="EO",5.2,IF(F41="EQ",3.9,IF(F41="ILF",7.5,IF(F41="EIF",5.4)))))) -> 5.2
...

Sheet 3.플랫폼 운영관리
B1: "산림공간 디지털플랫폼 사업_플랫폼 운영관리" 소프트웨어 개발비 산정
L2: (소프트웨어사업 대가산정 가이드, 2022. KOSA)
B4: ○ 개발원가 산정 | L4: (단위 : 원)
B5: 총기능점수 | D5: 기능점수당 단가 | F5: 보정계수 | K5: 개발원가
F6: 규모 | G6: 연계복잡성 | H6: 성능 | I6: 운영환경 | J6: 보안성
B7: =J30 -> 392.1 | D7: 605784 | F7: =K21 -> 1.28 | G7: =K22 -> 1 | H7: =K23 -> 1.05 | I7: =K24 -> 1.13 | J7: =K25 -> 1.03 | K7: =PRODUCT(B7:J7) -> 3.7156053e+08
B8: 합계(보정 후 개발원가) | K8: =SUM(K7:L7) -> 3.7156053e+08
B9: 이윤 | J9: 0.2 | K9: =K8*J9 -> 74312107
B10: 직접경비 | K10: =K17 -> 0
B11: 소프트웨어 개발비(부가세 별도) | K11: =SUM(K8:L10) -> 4.4587264e+08
B13: ○ 직접경비 | L13: (단위 : 원)
B14: 구분 | D14: 산출내역 | K14: 금액
B17: 합 계 | K17: =SUM(K15:L16) -> 0
B19: ○ 보정계수 산정
B20: 보정계수 구분 | D20: 복잡도 및 난이도 수준 | K20: 보정계수
B21: SW규모 | D21: ="= 0.4057 x (log e("&B7&") - 7.1978)^2 + 0.8878 (단, 500FP 미만 1.28, 3,000FP 초과 1.153 적용)" -> = 0.4057 x (log e(392.1) - 7.1978)^2 + 0.8878 (단, 500FP 미만 1.28, 3,000FP 초과 1.153 적용) | K21: =IF(B7<500,1.28,IF(B7>3000,1.153,0.4057*(LN(B7)-7.1978)^2+0.8878)) -> 1.28
B22: 연계복잡성 | D22: 3. 3~5개의 타 기관 연계 | K22: =VLOOKUP(D22,N22:O26,2,1) -> 1 | N22: 1. 타 기관 연계 없음 | O22: 0.88
B23: 성능 요구수준 | D23: 4. 응답시간이나 처리율이 모든 업무시간에 중요하며, 처리 시한이 명시되어 있다. | K23: =VLOOKUP(D23,N27:O31,2,1) -> 1.05 | N23: 2. 1~2개의 타 기관 연계 | O23: 0.94
B24: 운영환경 호환성 | D24: 4. 운영환경 호환성에 대한 요구사항이 있으며, 이질적인 하드웨어 및 소프트웨어 환경에서 운영되도록 설계된다. | K24: =VLOOKUP(D24,N32:O36,2,1) -> 1.13 | N24: 3. 3~5개의 타 기관 연계 | O24: 1
B25: 보안성 요구수준 | D25: 3. 3가지 요구사항이 포함되어 있다. | K25: =VLOOKUP(D25,N37:O41,2,1) -> 1.03 | N25: 4. 6~10개의 타 기관 연계 | O25: 1.06
N26: 5. 10개 초과의 타 기관 연계 | O26: 1.12
B27: ○ FP 집계 | N27: 1. 응답성능에 대한 특별한 요구사항이 없다. | O27: 0.91
B28: 구분 | E28: ILF | F28: EIF | G28: EI | H28: EO | I28: EQ | J28: 계 | N28: 2. 응답성능에 대한 요구사항이 있으나 특별한 조치가 필요하지는 않다. | O28: 0.95
B29: 기능수 | E29: =COUNTIF('3-1.FP산정(간이법)'!$F$5:$F10279,"ILF") -> 11 | F29: =COUNTIF('3-1.FP산정(간이법)'!$F$5:$F10279,"EIF") -> 1 | G29: =COUNTIF('3-1.FP산정(간이법)'!$F$5:$F10279,"EI") -> 39 | H29: =COUNTIF('3-1.FP산정(간이법)'!$F$5:$F10279,"EO") -> 6 | I29: =COUNTIF('3-1.FP산정(간이법)'!$F$5:$F10279,"EQ") -> 30 | J29: =SUM(E29:I29) -> 87 | N29: 3. 응답시간이나 처리율이 피크타임(peak time)에 중요하며, 처리 시한이 명시되어 있다. | O29: 1
B30: 기능점수 | E30: =SUMIF('3-1.FP산정(간이법)'!$F$5:$F10279,"ILF",'3-1.FP산정(간이법)'!$G$5:$G10279) -> 82.5 | F30: =SUMIF('3-1.FP산정(간이법)'!$F$5:$F10279,"EIF",'3-1.FP산정(간이법)'!$G$5:$G10279) -> 5.4 | G30: =SUMIF('3-1.FP산정(간이법)'!$F$5:$F10279,"EI",'3-1.FP산정(간이법)'!$G$5:$G10279) -> 156 | H30: =SUMIF('3-1.FP산정(간이법)'!$F$5:$F10279,"EO",'3-1.FP산정(간이법)'!$G$5:$G10279) -> 31.2 | I30: =SUMIF('3-1.FP산정(간이법)'!$F$5:$F10279,"EQ",'3-1.FP산정(간이법)'!$G$5:$G10279) -> 117 | J30: =SUM(E30:I30) -> 392.1 | N30: 4. 응답시간이나 처리율이 모든 업무시간에 중요하며, 처리 시한이 명시되어 있다. | O30: 1.05
B31: 비중 | E31: =IF($J$30>0,E30/$J$30,"-") -> 0.21040551 | F31: =IF($J$30>0,F30/$J$30,"-") -> 0.013771997 | G31: =IF($J$30>0,G30/$J$30,"-") -> 0.39785769 | H31: =IF($J$30>0,H30/$J$30,"-") -> 0.079571538 | I31: =IF($J$30>0,I30/$J$30,"-") -> 0.29839327 | J31: =SUM(E31:I31) -> 1 | N31: 5. 응답성능 요구수준이 엄격하여, 설계, 개발 또는 구현 단계에서 성능 분석도구 사용이 필요하다. | O31: 1.09
N32: 1. 운영환경 호환성에 대한 요구사항이 없다. | O32: 0.94
N33: 2. 운영환경 호환성에 대한 요구사항이 있으며, 동일 하드웨어 및 소프트웨어 환경에서 운영되도록 설계된다. | O33: 1
N34: 3. 운영환경 호환성에 대한 요구사항이 있으며, 유사 하드웨어 및 소프트웨어 환경에서 운영되도록 설계된다. | O34: 1.06
N35: 4. 운영환경 호환성에 대한 요구사항이 있으며, 이질적인 하드웨어 및 소프트웨어 환경에서 운영되도록 설계된다. | O35: 1.13
N36: 5. 항목 4에 더하여 일반적 산출물 이외에 장소에서 원활한 운영을 보장하기 위한 운영 절차의 문서화와 사전 모의훈련이 요구된다. | O36: 1.19
N37: 1. 암호화, 웹취약점 점검, 시큐어코딩, 개인정보보호 등 1가지 보안 요구사항이 포함되어 있다. | O37: 0.97
N38: 2. 2가지 요구사항이 포함되어 있다. | O38: 1
N39: 3. 3가지 요구사항이 포함되어 있다. | O39: 1.03
N40: 4. 4가지 항목이 모두 포함되어 있다. | O40: 1.06
N41: 5. 5가지 이상의 보안 요구사항이 포함되어 있다. | O41: 1.08

Sheet 3-1.FP산정(간이법)
B1: 기능점수 산정 (간이법)
B3: 기능명 | F3: 데이터 및 트랜잭션 기능 | G3: FP 산출 | H3: 비고
B4: ①어플리케이션명 | C4: ②세부 업무명 | D4: ③단위프로세스명 | E4: 단위프로세스 설명 | F4: ④FP유형 | G4: ⑤가중치
B5: 운영관리 | C5: 사용자 관리 | D5: 사용자 정보 | F5: ILF | G5: =IF(F5="","",IF(F5="EI",4,IF(F5="EO",5.2,IF(F5="EQ",3.9,IF(F5="ILF",7.5,IF(F5="EIF",5.4)))))) -> 7.5
B6: 운영관리 | C6: 사용자 관리 | D6: 사용자 목록조회 | F6: EQ | G6: =IF(F6="","",IF(F6="EI",4,IF(F6="EO",5.2,IF(F6="EQ",3.9,IF(F6="ILF",7.5,IF(F6="EIF",5.4)))))) -> 3.9
B7: 운영관리 | C7: 사용자 관리 | D7: 사용자 상세조회 | F7: EQ | G7: =IF(F7="","",IF(F7="EI",4,IF(F7="EO",5.2,IF(F7="EQ",3.9,IF(F7="ILF",7.5,IF(F7="EIF",5.4)))))) -> 3.9
B8: 운영관리 | C8: 사용자 관리 | D8: 사용자 추가(등록) | F8: EI | G8: =IF(F8="","",IF(F8="EI",4,IF(F8="EO",5.2,IF(F8="EQ",3.9,IF(F8="ILF",7.5,IF(F8="EIF",5.4)))))) -> 4
B9: 운영관리 | C9: 사용자 관리 | D9: 사용자 수정 | F9: EI | G9: =IF(F9="","",IF(F9="EI",4,IF(F9="EO",5.2,IF(F9="EQ",3.9,IF(F9="ILF",7.5,IF(F9="EIF",5.4)))))) -> 4
B10: 운영관리 | C10: 사용자 관리 | D10: 사용자 삭제 | F10: EI | G10: =IF(F10="","",IF(F10="EI",4,IF(F10="EO",5.2,IF(F10="EQ",3.9,IF(F10="ILF",7.5,IF(F10="EIF",5.4)))))) -> 4
B11: 운영관리 | C11: 사용자 권한관리 | D11: 사용자 권한 정보 | F11: ILF | G11: =IF(F11="","",IF(F11="EI",4,IF(F11="EO",5.2,IF(F11="EQ",3.9,IF(F11="ILF",7.5,IF(F11="EIF",5.4)))))) -> 7.5
B12: 운영관리 | C12: 사용자 권한관리 | D12: 사용자 권한 목록조회 | F12: EQ | G12: =IF(F12="","",IF(F12="EI",4,IF(F12="EO",5.2,IF(F12="EQ",3.9,IF(F12="ILF",7.5,IF(F12="EIF",5.4)))))) -> 3.9
B13: 운영관리 | C13: 사용자 권한관리 | D13: 사용자 권한 상세조회 | F13: EQ | G13: =IF(F13="","",IF(F13="EI",4,IF(F13="EO",5.2,IF(F13="EQ",3.9,IF(F13="ILF",7.5,IF(F13="EIF",5.4)))))) -> 3.9
B14: 운영관리 | C14: 사용자 권한관리 | D14: 사용자 권한 등록 | F14: EI | G14: =IF(F14="","",IF(F14="EI",4,IF(F14="EO",5.2,IF(F14="EQ",3.9,IF(F14="ILF",7.5,IF(F14="EIF",5.4)))))) -> 4
B15: 운영관리 | C15: 사용자 권한관리 | D15: 사용자 권한 수정 | F15: EI | G15: =IF(F15="","",IF(F15="EI",4,IF(F15="EO",5.2,IF(F15="EQ",3.9,IF(F15="ILF",7.5,IF(F15="EIF",5.4)))))) -> 4
B16: 운영관리 | C16: 사용자 권한관리 | D16: 사용자 권한 삭제 | F16: EI | G16: =IF(F16="","",IF(F16="EI",4,IF(F16="EO",5.2,IF(F16="EQ",3.9,IF(F16="ILF",7.5,IF(F16="EIF",5.4)))))) -> 4
... B35: 운영관리 | C35: 공간정보 권한 관리 | D35: 공간데이터 권한 삭제 | F35: EI | G35: =IF(F35="","",IF(F35="EI",4,IF(F35="EO",5.2,IF(F35="EQ",3.9,IF(F35="ILF",7.5,IF(F35="EIF",5.4)))))) -> 4
B36: 운영관리 | C36: 공통코드 관리 | D36: 공통코드 관리 DB | E36: 코드정보 DB | F36: ILF | G36: =IF(F36="","",IF(F36="EI",4,IF(F36="EO",5.2,IF(F36="EQ",3.9,IF(F36="ILF",7.5,IF(F36="EIF",5.4)))))) -> 7.5
B37: 운영관리 | C37: 공통코드 관리 | D37: 공통코드 그룹 목록 조회 | E37: 공통코드 그룹 목록을 조회한다. | F37: EQ | G37: =IF(F37="","",IF(F37="EI",4,IF(F37="EO",5.2,IF(F37="EQ",3.9,IF(F37="ILF",7.5,IF(F37="EIF",5.4)))))) -> 3.9
B38: 운영관리 | C38: 공통코드 관리 | D38: 공통코드 그룹 상세정보 조회 | E38: 공통코드 그룹을 상세정보 조회한다. | F38: EQ | G38: =IF(F38="","",IF(F38="EI",4,IF(F38="EO",5.2,IF(F38="EQ",3.9,IF(F38="ILF",7.5,IF(F38="EIF",5.4)))))) -> 3.9
B39: 운영관리 | C39: 공통코드 관리 | D39: 공통코드 그룹 등록 | E39: 공통코드 그룹을 신규 등록한다. | F39: EI | G39: =IF(F39="","",IF(F39="EI",4,IF(F39="EO",5.2,IF(F39="EQ",3.9,IF(F39="ILF",7.5,IF(F39="EIF",5.4)))))) -> 4
B40: 운영관리 | C40: 공통코드 관리 | D40: 공통코드 그룹 수정 | E40: 공통코드 그룹을 수정한다. | F40: EI | G40: =IF(F40="","",IF(F40="EI",4,IF(F40="EO",5.2,IF(F40="EQ",3.9,IF(F40="ILF",7.5,IF(F40="EIF",5.4)))))) -> 4
B41: 운영관리 | C41: 공통코드 관리 | D41: 공통코드 그룹 삭제 | E41: 공통코드 그룹을 삭제한다. | F41: EI | G41: =IF(F41="","",IF(F41="EI",4,IF(F41="EO",5.2,IF(F41="EQ",3.9,IF(F41="ILF",7.5,IF(F41="EIF",5.4)))))) -> 4
B42: 운영관리 | C42: 공통코드 관리 | D42: 상세코드 정보 등록 | E42: 상세코드 정보를 신규 등록한다. | F42: EI | G42: =IF(F42="","",IF(F42="EI",4,IF(F42="EO",5.2,IF(F42="EQ",3.9,IF(F42="ILF",7.5,IF(F42="EIF",5.4)))))) -> 4
B43: 운영관리 | C43: 공통코드 관리 | D43: 상세코드 정보 수정 | E43: 상세코드 정보를 수정한다. | F43: EI | G43: =IF(F43="","",IF(F43="EI",4,IF(F43="EO",5.2,IF(F43="EQ",3.9,IF(F43="ILF",7.5,IF(F43="EIF",5.4)))))) -> 4
B44: 운영관리 | C44: 공통코드 관리 | D44: 상세코드 정보 삭제 | E44: 상세코드 정보를 삭제한다. | F44: EI | G44: =IF(F44="","",IF(F44="EI",4,IF(F44="EO",5.2,IF(F44="EQ",3.9,IF(F44="ILF",7.5,IF(F44="EIF",5.4)))))) -> 4
B45: 운영관리 | C45: 메뉴 관리 | D45: 메뉴 관리정보 DB | E45: 메뉴관리정보 DB | F45: ILF | G45: =IF(F45="","",IF(F45="EI",4,IF(F45="EO",5.2,IF(F45="EQ",3.9,IF(F45="ILF",7.5,IF(F45="EIF",5.4)))))) -> 7.5
B46: 운영관리 | C46: 메뉴 관리 | D46: 메뉴 목록 조회 | E46: 메뉴관리 목록을 조회한다. | F46: EQ | G46: =IF(F46="","",IF(F46="EI",4,IF(F46="EO",5.2,IF(F46="EQ",3.9,IF(F46="ILF",7.5,IF(F46="EIF",5.4)))))) -> 3.9
B47: 운영관리 | C47: 메뉴 관리 | D47: 메뉴 상세 조회 | E47: 메뉴관리 상세정보 조회를 한다. | F47: EQ | G47: =IF(F47="","",IF(F47="EI",4,IF(F47="EO",5.2,IF(F47="EQ",3.9,IF(F47="ILF",7.5,IF(F47="EIF",5.4)))))) -> 3.9
... B78: 운영관리 | C78: Q&A 관리 | D78: Q&A 삭제 | E78: 잘못된 Q&A건은 관리자가 삭제할 수 있다. | F78: EI | G78: =IF(F78="","",IF(F78="EI",4,IF(F78="EO",5.2,IF(F78="EQ",3.9,IF(F78="ILF",7.5,IF(F78="EIF",5.4)))))) -> 4
B79: 운영관리 | C79: 플랫폼 API 관리 | D79: 플랫폼 API 정보 | F79: ILF | G79: =IF(F79="","",IF(F79="EI",4,IF(F79="EO",5.2,IF(F79="EQ",3.9,IF(F79="ILF",7.5,IF(F79="EIF",5.4)))))) -> 7.5
B80: 운영관리 | C80: 플랫폼 API 관리 | D80: 플랫폼 API 목록조회 | F80: EQ | G80: =IF(F80="","",IF(F80="EI",4,IF(F80="EO",5.2,IF(F80="EQ",3.9,IF(F80="ILF",7.5,IF(F80="EIF",5.4)))))) -> 3.9
B81: 운영관리 | C81: 플랫폼 API 관리 | D81: 플랫폼 API 상세조회 | F81: EQ | G81: =IF(F81="","",IF(F81="EI",4,IF(F81="EO",5.2,IF(F81="EQ",3.9,IF(F81="ILF",7.5,IF(F81="EIF",5.4)))))) -> 3.9
B82: 운영관리 | C82: 플랫폼 API 관리 | D82: 플랫폼 API 등록 | E82: 외부기관(시스템)에서 사용할 API에 대해 등록하고 사용제한 등을 설정한다. | F82: EI | G82: =IF(F82="","",IF(F82="EI",4,IF(F82="EO",5.2,IF(F82="EQ",3.9,IF(F82="ILF",7.5,IF(F82="EIF",5.4)))))) -> 4
B83: 운영관리 | C83: 플랫폼 API 관리 | D83: 플랫폼 API 수정 | F83: EI | G83: =IF(F83="","",IF(F83="EI",4,IF(F83="EO",5.2,IF(F83="EQ",3.9,IF(F83="ILF",7.5,IF(F83="EIF",5.4)))))) -> 4
B84: 운영관리 | C84: 플랫폼 API 관리 | D84: 플랫폼 API 삭제 | F84: EI | G84: =IF(F84="","",IF(F84="EI",4,IF(F84="EO",5.2,IF(F84="EQ",3.9,IF(F84="ILF",7.5,IF(F84="EIF",5.4)))))) -> 4
B85: 운영관리 | C85: API 요청 관리 | D85: API 요청 정보 | F85: ILF | G85: =IF(F85="","",IF(F85="EI",4,IF(F85="EO",5.2,IF(F85="EQ",3.9,IF(F85="ILF",7.5,IF(F85="EIF",5.4)))))) -> 7.5
B86: 운영관리 | C86: API 요청 관리 | D86: API 요청 목록조회 | F86: EQ | G86: =IF(F86="","",IF(F86="EI",4,IF(F86="EO",5.2,IF(F86="EQ",3.9,IF(F86="ILF",7.5,IF(F86="EIF",5.4)))))) -> 3.9
B87: 운영관리 | C87: API 요청 관리 | D87: API 요청 상세조회 | F87: EQ | G87: =IF(F87="","",IF(F87="EI",4,IF(F87="EO",5.2,IF(F87="EQ",3.9,IF(F87="ILF",7.5,IF(F87="EIF",5.4)))))) -> 3.9
B88: 운영관리 | C88: API 요청 관리 | D88: API 사용 승인 | E88: 플랫폼 API 요청에 의한 승인 및 인증키를 발급한다. | F88: EI | G88: =IF(F88="","",IF(F88="EI",4,IF(F88="EO",5.2,IF(F88="EQ",3.9,IF(F88="ILF",7.5,IF(F88="EIF",5.4)))))) -> 4
B89: 운영관리 | C89: API 요청 관리 | D89: API 사용 삭제 | F89: EI | G89: =IF(F89="","",IF(F89="EI",4,IF(F89="EO",5.2,IF(F89="EQ",3.9,IF(F89="ILF",7.5,IF(F89="EIF",5.4)))))) -> 4
...

Sheet 4.2D 및 3D 특화서비스
B1: "산림공간 디지털플랫폼 사업_2D,3D 특화서비스" 소프트웨어 재개발비 산정
N2: (소프트웨어사업 대가산정 가이드, 2024. KOSA)
B4: ○ 재개발비 산정 | N4: (단위 : 원)
B5: 신규개발 | E5: 신규개발 기능 규모 | G5: ='4-1.FP산정(재개발, 간이법)'!K2 -> 185.4
B6: 수정없이 재사용 | E6: 수정없이 재사용 대상 기능 규모 | G6: ='4-1.FP산정(재개발, 간이법)'!K5 -> 0 | J6: 시험단계 비율 (0~25%) | M6: 0.25
E7: 수정없이 재사용 기능 규모 | G7: =G6*M6 -> 0
B8: 수정 후 재사용 | E8: 기능변경 규모 | G8: ='4-1.FP산정(재개발, 간이법)'!K3 -> 444.8
E9: 재사용 난이도 | G9: =1+((L9+L10)/2)/100*0.8 -> 1.28 | I9: 구조화 및 애플리케이션 명확화 정도 | L9: =HLOOKUP(N9,P9:T10,2,FALSE) -> 40 | N9: 어려움 | P9: 매우 어려움 | Q9: 어려움 | R9: 보통 | S9: 쉬움 | T9: 매우 쉬움
I10: 문서화 및 소스코드 서술화 정도 | L10: =HLOOKUP(N10,P9:T10,2,0) -> 30 | N10: 보통 | P10: 50 | Q10: 40 | R10: 30 | S10: 20 | T10: 10
E11: 수정 후 재사용 기능 규모 | G11: =G8*G9 -> 569.344
B12: 재개발 기능 규모 | E12: =G5+G7+G11 -> 754.744 | K12: 기능점수당 단가 | M12: 605784
B13: 보정전 재개발원가 | E13: =E12*M12 -> 4.5721184e+08
B14: 보정계수 | E14: 규모 | G14: 연계복잡성 | I14: 성능 | K14: 운영환경 호환성 | M14: 보안성
E15: =M32 -> 1.0202701 | G15: =M33 -> 1 | I15: =M34 -> 1.05 | K15: =M35 -> 1.13 | M15: =M36 -> 1.03
B16: 보정후 재개발원가 | E16: =E13*E15*G15*I15*K15*M15 -> 5.7008237e+08
B17: 직접경비 | E17: =M28 -> 0
B18: 이윤 | D18: 0.2 | E18: =E16*D18 -> 1.1401647e+08
B19: 재개발 사업대가 (부가세 별도) | E19: =SUM(E16:N18) -> 6.8409884e+08
B20: 재개발 사업대가 (부가세 포함) | E20: =E19*1.1 -> 7.5250873e+08
B23: ○ 직접경비 | N23: (단위 : 원)
B24: 항목 | E24: 산출내역 | M24: 금액
B28: 합 계 | M28: =SUM(M25:N27) -> 0
B30: ※ 보정계수 산정
B31: 보정계수 구분 | E31: 복잡도 및 난이도 수준 | M31: 보정계수
B32: SW규모 | E32: ="= 0.4057 x (log e("&E12&") - 7.1978)^2 + 0.8878 (단, 500FP 미만 1.28, 3,000FP 초과 1.153 적용)" -> = 0.4057 x (log e(754.744) - 7.1978)^2 + 0.8878 (단, 500FP 미만 1.28, 3,000FP 초과 1.153 적용) | M32: =IF(E12<500,1.28,IF(E12>3000,1.153,0.4057*(LN(E12)-7.1978)^2+0.8878)) -> 1.0202701
B33: 연계복잡성 | E33: 3. 3~5개의 타 기관 연계 | M33: =VLOOKUP(E33,P33:Q37,2,1) -> 1 | P33: 1. 타 기관 연계 없음 | Q33: 0.88
B34: 성능 요구수준 | E34: 4. 응답시간이나 처리율이 모든 업무시간에 중요하며, 처리 시한이 명시되어 있다. | M34: =VLOOKUP(E34,P38:Q42,2,1) -> 1.05 | P34: 2. 1~2개의 타 기관 연계 | Q34: 0.94
B35: 운영환경 호환성 | E35: 4. 운영환경 호환성에 대한 요구사항이 있으며, 이질적인 하드웨어 및 소프트웨어 환경에서 운영되도록 설계된다. | M35: =VLOOKUP(E35,P43:Q47,2,1) -> 1.13 | P35: 3. 3~5개의 타 기관 연계 | Q35: 1
B36: 보안성 요구수준 | E36: 3. 3가지 요구사항이 포함되어 있다. | M36: =VLOOKUP(E36,P48:Q52,2,1) -> 1.03 | P36: 4. 6~10개의 타 기관 연계 | Q36: 1.06
P37: 5. 10개 초과의 타 기관 연계 | Q37: 1.12
P38: 1. 응답성능에 대한 특별한 요구사항이 없다. | Q38: 0.91
P39: 2. 응답성능에 대한 요구사항이 있으나 특별한 조치가 필요하지는 않다. | Q39: 0.95
P40: 3. 응답시간이나 처리율이 피크타임(peak time)에 중요하며, 처리 시한이 명시되어 있다. | Q40: 1
P41: 4. 응답시간이나 처리율이 모든 업무시간에 중요하며, 처리 시한이 명시되어 있다. | Q41: 1.05
P42: 5. 응답성능 요구수준이 엄격하여, 설계, 개발 또는 구현 단계에서 성능 분석도구 사용이 필요하다. | Q42: 1.09
P43: 1. 운영환경 호환성에 대한 요구사항이 없다. | Q43: 0.94
P44: 2. 운영환경 호환성에 대한 요구사항이 있으며, 동일 하드웨어 및 소프트웨어 환경에서 운영되도록 설계된다. | Q44: 1
P45: 3. 운영환경 호환성에 대한 요구사항이 있으며, 유사 하드웨어 및 소프트웨어 환경에서 운영되도록 설계된다. | Q45: 1.06
P46: 4. 운영환경 호환성에 대한 요구사항이 있으며, 이질적인 하드웨어 및 소프트웨어 환경에서 운영되도록 설계된다. | Q46: 1.13
P47: 5. 항목 4에 더하여 일반적 산출물 이외에 장소에서 원활한 운영을 보장하기 위한 운영 절차의 문서화와 사전 모의훈련이 요구된다. | Q47: 1.19
...

Sheet 4-1.FP산정(재개발, 간이법)
B2: 기능점수 산정 | J2: 신규개발 | K2: =SUMIF(J:J,J2,I:I) -> 185.4
J3: 기능변경 | K3: =SUMIF(J:J,J3,Q:Q) -> 444.8
J4: 기능삭제 | K4: 측정 비대상
J5: 수정없이 재사용 | K5: =SUMIF(J:J,J5,I:I) -> 0
F6: EIF | G6: = 관리주체가 외부에 있으므로 기능변경 측정 대상이 아님에 유의
B7: 기능명 | F7: 데이터 및 트랜잭션 기능 | I7: FP 산출 | J7: 재사용유형 | K7: FTR 변경량 | L7: DET 변경량 | M7: FTR 변경률 | N7: DET 변경률 | O7: 기능 변경률 | P7: 영향 계수 | Q7: 재사용 기능점수 | R7: 비고
B8: ①어플리케이션명 | C8: ②세부 업무명 | D8: ③단위프로세스명 | E8: 단위프로세스 설명 | F8: ④FP유형 | G8: ⑤FTR | H8: ⑥DET | I8: ⑧가중치
B9: □ 2D 지도 Community | I9: =IF(F9="","",IF(F9="EI",4,IF(F9="EO",5.2,IF(F9="EQ",3.9,IF(F9="ILF",7.5,IF(F9="EIF",5.4)))))) | M9: =IFERROR(IF(J9="기능변경",K9/G9,""),"") | N9: =IFERROR(IF(J9="기능변경",L9/H9,""),"") | O9: =IF(J9="기능변경",IF(F9="ILF",N9,IF(F9="EIF","재검토",IF(M9=0,N9,IF(N9=0,M9,(M9+N9)/2)))),"") | P9: =IF(O9<>0,IF(J9="기능변경",IF(O9<=0.33,0.25,IF(O9>0.66,0.75,0.5)),IF(J9="기능삭제",0,"")),"") | Q9: =IFERROR(I9*P9,"")
B10: 기본 도구 제공 | C10: 지오코딩 | D10: EXCEL 파일 지오코딩 | E10: EXCEL 파일 지오코딩 기능을 제공한다. | F10: EQ | G10: 4 | H10: 4 | I10: =IF(F10="","",IF(F10="EI",4,IF(F10="EO",5.2,IF(F10="EQ",3.9,IF(F10="ILF",7.5,IF(F10="EIF",5.4)))))) -> 3.9 | J10: 기능변경 | K10: 1 | L10: 1 | M10: =IFERROR(IF(J10="기능변경",K10/G10,""),"") -> 0.25 | N10: =IFERROR(IF(J10="기능변경",L10/H10,""),"") -> 0.25 | O10: =IF(J10="기능변경",IF(F10="ILF",N10,IF(F10="EIF","재검토",IF(M10=0,N10,IF(N10=0,M10,(M10+N10)/2)))),"") -> 0.25 | P10: =IF(O10<>0,IF(J10="기능변경",IF(O10<=0.33,0.25,IF(O10>0.66,0.75,0.5)),IF(J10="기능삭제",0,"")),"") -> 0.25 | Q10: =IFERROR(I10*P10,"") -> 0.975
B11: 기본 도구 제공 | C11: 지오코딩 | D11: CSV 파일 지오코딩 | E11: CSV 파일 지오코딩 기능을 제공한다. | F11: EQ | G11: 4 | H11: 4 | I11: =IF(F11="","",IF(F11="EI",4,IF(F11="EO",5.2,IF(F11="EQ",3.9,IF(F11="ILF",7.5,IF(F11="EIF",5.4)))))) -> 3.9 | J11: 기능변경 | K11: 1 | L11: 1 | M11: =IFERROR(IF(J11="기능변경",K11/G11,""),"") -> 0.25 | N11: =IFERROR(IF(J11="기능변경",L11/H11,""),"") -> 0.25 | O11: =IF(J11="기능변경",IF(F11="ILF",N11,IF(F11="EIF","재검토",IF(M11=0,N11,IF(N11=0,M11,(M11+N11)/2)))),"") -> 0.25 | P11: =IF(O11<>0,IF(J11="기능변경",IF(O11<=0.33,0.25,IF(O11>0.66,0.75,0.5)),IF(J11="기능삭제",0,"")),"") -> 0.25 | Q11: =IFERROR(I11*P11,"") -> 0.975
B12: 기본 도구 제공 | C12: 공간정보 파일 업로드 | D12: SHP 압축파일 업로드 | E12: SHP 압축파일 업로드 기능을 제공한다. | F12: EQ | G12: 4 | H12: 4 | I12: =IF(F12="","",IF(F12="EI",4,IF(F12="EO",5.2,IF(F12="EQ",3.9,IF(F12="ILF",7.5,IF(F12="EIF",5.4)))))) -> 3.9 | J12: 기능변경 | K12: 1 | L12: 1 | M12: =IFERROR(IF(J12="기능변경",K12/G12,""),"") -> 0.25 | N12: =IFERROR(IF(J12="기능변경",L12/H12,""),"") -> 0.25 | O12: =IF(J12="기능변경",IF(F12="ILF",N12,IF(F12="EIF","재검토",IF(M12=0,N12,IF(N12=0,M12,(M12+N12)/2)))),"") -> 0.25 | P12: =IF(O12<>0,IF(J12="기능변경",IF(O12<=0.33,0.25,IF(O12>0.66,0.75,0.5)),IF(J12="기능삭제",0,"")),"") -> 0.25 | Q12: =IFERROR(I12*P12,"") -> 0.975
B13: 기본 도구 제공 | C13: 공간정보 파일 업로드 | D13: DXF 파일 업로드 | E13: DXF 파일 업로드 기능을 제공한다. | F13: EQ | G13: 4 | H13: 4 | I13: =IF(F13="","",IF(F13="EI",4,IF(F13="EO",5.2,IF(F13="EQ",3.9,IF(F13="ILF",7.5,IF(F13="EIF",5.4)))))) -> 3.9 | J13: 기능변경 | K13: 1 | L13: 1 | M13: =IFERROR(IF(J13="기능변경",K13/G13,""),"") -> 0.25 | N13: =IFERROR(IF(J13="기능변경",L13/H13,""),"") -> 0.25 | O13: =IF(J13="기능변경",IF(F13="ILF",N13,IF(F13="EIF","재검토",IF(M13=0,N13,IF(N13=0,M13,(M13+N13)/2)))),"") -> 0.25 | P13: =IF(O13<>0,IF(J13="기능변경",IF(O13<=0.33,0.25,IF(O13>0.66,0.75,0.5)),IF(J13="기능삭제",0,"")),"") -> 0.25 | Q13: =IFERROR(I13*P13,"") -> 0.975
B14: 기본 도구 제공 | C14: 공간정보 파일 업로드 | D14: TIF 파일 업로드 | E14: TIF 파일 업로드 기능을 제공한다. | F14: EQ | G14: 4 | H14: 4 | I14: =IF(F14="","",IF(F14="EI",4,IF(F14="EO",5.2,IF(F14="EQ",3.9,IF(F14="ILF",7.5,IF(F14="EIF",5.4)))))) -> 3.9 | J14: 기능변경 | K14: 1 | L14: 1 | M14: =IFERROR(IF(J14="기능변경",K14/G14,""),"") -> 0.25 | N14: =IFERROR(IF(J14="기능변경",L14/H14,""),"") -> 0.25 | O14: =IF(J14="기능변경",IF(F14="ILF",N14,IF(F14="EIF","재검토",IF(M14=0,N14,IF(N14=0,M14,(M14+N14)/2)))),"") -> 0.25 | P14: =IF(O14<>0,IF(J14="기능변경",IF(O14<=0.33,0.25,IF(O14>0.66,0.75,0.5)),IF(J14="기능삭제",0,"")),"") -> 0.25 | Q14: =IFERROR(I14*P14,"") -> 0.975
B15: 기본 도구 제공 | C15: 공간정보 파일 업로드 | D15: GeoJSON 업로드 | E15: GeoJSON 업로드 기능을 제공한다. | F15: EQ | G15: 4 | H15: 4 | I15: =IF(F15="","",IF(F15="EI",4,IF(F15="EO",5.2,IF(F15="EQ",3.9,IF(F15="ILF",7.5,IF(F15="EIF",5.4)))))) -> 3.9 | J15: 기능변경 | K15: 1 | L15: 1 | M15: =IFERROR(IF(J15="기능변경",K15/G15,""),"") -> 0.25 | N15: =IFERROR(IF(J15="기능변경",L15/H15,""),"") -> 0.25 | O15: =IF(J15="기능변경",IF(F15="ILF",N15,IF(F15="EIF","재검토",IF(M15=0,N15,IF(N15=0,M15,(M15+N15)/2)))),"") -> 0.25 | P15: =IF(O15<>0,IF(J15="기능변경",IF(O15<=0.33,0.25,IF(O15>0.66,0.75,0.5)),IF(J15="기능삭제",0,"")),"") -> 0.25 | Q15: =IFERROR(I15*P15,"") -> 0.975
B16: 기본 도구 제공 | C16: 좌표 변환 도구 | D16: 공간정보 파일 좌표변환 | E16: 공간정보 파일 좌표변환 기능을 제공한다. | F16: EO | G16: 4 | H16: 4 | I16: =IF(F16="","",IF(F16="EI",4,IF(F16="EO",5.2,IF(F16="EQ",3.9,IF(F16="ILF",7.5,IF(F16="EIF",5.4)))))) -> 5.2 | J16: 기능변경 | K16: 1 | L16: 1 | M16: =IFERROR(IF(J16="기능변경",K16/G16,""),"") -> 0.25 | N16: =IFERROR(IF(J16="기능변경",L16/H16,""),"") -> 0.25 | O16: =IF(J16="기능변경",IF(F16="ILF",N16,IF(F16="EIF","재검토",IF(M16=0,N16,IF(N16=0,M16,(M16+N16)/2)))),"") -> 0.25 | P16: =IF(O16<>0,IF(J16="기능변경",IF(O16<=0.33,0.25,IF(O16>0.66,0.75,0.5)),IF(J16="기능삭제",0,"")),"") -> 0.25 | Q16: =IFERROR(I16*P16,"") -> 1.3
B17: 기본 도구 제공 | C17: 주소 검색 | D17: 지번 주소 검색 | E17: 지번 주소 검색 기능을 제공한다. | F17: EQ | G17: 4 | H17: 4 | I17: =IF(F17="","",IF(F17="EI",4,IF(F17="EO",5.2,IF(F17="EQ",3.9,IF(F17="ILF",7.5,IF(F17="EIF",5.4)))))) -> 3.9 | J17: 기능변경 | K17: 1 | L17: 1 | M17: =IFERROR(IF(J17="기능변경",K17/G17,""),"") -> 0.25 | N17: =IFERROR(IF(J17="기능변경",L17/H17,""),"") -> 0.25 | O17: =IF(J17="기능변경",IF(F17="ILF",N17,IF(F17="EIF","재검토",IF(M17=0,N17,IF(N17=0,M17,(M17+N17)/2)))),"") -> 0.25 | P17: =IF(O17<>0,IF(J17="기능변경",IF(O17<=0.33,0.25,IF(O17>0.66,0.75,0.5)),IF(J17="기능삭제",0,"")),"") -> 0.25 | Q17: =IFERROR(I17*P17,"") -> 0.975
B18: 기본 도구 제공 | C18: 주소 검색 | D18: 도로명 주소 검색 | E18: 도로명 주소 검색 기능을 제공한다. | F18: EQ | G18: 4 | H18: 4 | I18: =IF(F18="","",IF(F18="EI",4,IF(F18="EO",5.2,IF(F18="EQ",3.9,IF(F18="ILF",7.5,IF(F18="EIF",5.4)))))) -> 3.9 | J18: 기능변경 | K18: 1 | L18: 1 | M18: =IFERROR(IF(J18="기능변경",K18/G18,""),"") -> 0.25 | N18: =IFERROR(IF(J18="기능변경",L18/H18,""),"") -> 0.25 | O18: =IF(J18="기능변경",IF(F18="ILF",N18,IF(F18="EIF","재검토",IF(M18=0,N18,IF(N18=0,M18,(M18+N18)/2)))),"") -> 0.25 | P18: =IF(O18<>0,IF(J18="기능변경",IF(O18<=0.33,0.25,IF(O18>0.66,0.75,0.5)),IF(J18="기능삭제",0,"")),"") -> 0.25 | Q18: =IFERROR(I18*P18,"") -> 0.975
B19: 기본 도구 제공 | C19: 주소 검색 | D19: 과거지번 주소 검색 | E19: 과거지번 주소 기능을 제공한다. | F19: EQ | G19: 4 | H19: 4 | I19: =IF(F19="","",IF(F19="EI",4,IF(F19="EO",5.2,IF(F19="EQ",3.9,IF(F19="ILF",7.5,IF(F19="EIF",5.4)))))) -> 3.9 | J19: 기능변경 | K19: 1 | L19: 1 | M19: =IFERROR(IF(J19="기능변경",K19/G19,""),"") -> 0.25 | N19: =IFERROR(IF(J19="기능변경",L19/H19,""),"") -> 0.25 | O19: =IF(J19="기능변경",IF(F19="ILF",N19,IF(F19="EIF","재검토",IF(M19=0,N19,IF(N19=0,M19,(M19+N19)/2)))),"") -> 0.25 | P19: =IF(O19<>0,IF(J19="기능변경",IF(O19<=0.33,0.25,IF(O19>0.66,0.75,0.5)),IF(J19="기능삭제",0,"")),"") -> 0.25 | Q19: =IFERROR(I19*P19,"") -> 0.975
B20: 기본 도구 제공 | C20: 주소 검색 | D20: POI(명칭) 검색 | E20: POI(명칭)을 주소를 검색한다. | F20: EQ | G20: 4 | H20: 4 | I20: =IF(F20="","",IF(F20="EI",4,IF(F20="EO",5.2,IF(F20="EQ",3.9,IF(F20="ILF",7.5,IF(F20="EIF",5.4)))))) -> 3.9 | J20: 기능변경 | K20: 1 | L20: 1 | M20: =IFERROR(IF(J20="기능변경",K20/G20,""),"") -> 0.25 | N20: =IFERROR(IF(J20="기능변경",L20/H20,""),"") -> 0.25 | O20: =IF(J20="기능변경",IF(F20="ILF",N20,IF(F20="EIF","재검토",IF(M20=0,N20,IF(N20=0,M20,(M20+N20)/2)))),"") -> 0.25 | P20: =IF(O20<>0,IF(J20="기능변경",IF(O20<=0.33,0.25,IF(O20>0.66,0.75,0.5)),IF(J20="기능삭제",0,"")),"") -> 0.25 | Q20: =IFERROR(I20*P20,"") -> 0.975
B21: 기본 도구 제공 | C21: 주소 검색 | D21: PNU로 주소 검색 | E21: PNU로 최신 지번 주소 및 도로명 주소를 검색한다. | F21: EQ | G21: 4 | H21: 4 | I21: =IF(F21="","",IF(F21="EI",4,IF(F21="EO",5.2,IF(F21="EQ",3.9,IF(F21="ILF",7.5,IF(F21="EIF",5.4)))))) -> 3.9 | J21: 기능변경 | K21: 1 | L21: 1 | M21: =IFERROR(IF(J21="기능변경",K21/G21,""),"") -> 0.25 | N21: =IFERROR(IF(J21="기능변경",L21/H21,""),"") -> 0.25 | O21: =IF(J21="기능변경",IF(F21="ILF",N21,IF(F21="EIF","재검토",IF(M21=0,N21,IF(N21=0,M21,(M21+N21)/2)))),"") -> 0.25 | P21: =IF(O21<>0,IF(J21="기능변경",IF(O21<=0.33,0.25,IF(O21>0.66,0.75,0.5)),IF(J21="기능삭제",0,"")),"") -> 0.25 | Q21: =IFERROR(I21*P21,"") -> 0.975
... B236: 기본 레이어 설정 | C236: 사용자 별 초기 설정 | D236: 사용자 별 초기 설정 정보 삭제 | E236: 사용자 별 초기 설정 정보를 삭제한다. | F236: EI | G236: 4 | H236: 4 | I236: =IF(F236="","",IF(F236="EI",4,IF(F236="EO",5.2,IF(F236="EQ",3.9,IF(F236="ILF",7.5,IF(F236="EIF",5.4)))))) -> 4 | J236: 기능변경 | K236: 1 | L236: 1 | M236: =IFERROR(IF(J236="기능변경",K236/G236,""),"") -> 0.25 | N236: =IFERROR(IF(J236="기능변경",L236/H236,""),"") -> 0.25 | O236: =IF(J236="기능변경",IF(F236="ILF",N236,IF(F236="EIF","재검토",IF(M236=0,N236,IF(N236=0,M236,(M236+N236)/2)))),"") -> 0.25 | P236: =IF(O236<>0,IF(J236="기능변경",IF(O236<=0.33,0.25,IF(O236>0.66,0.75,0.5)),IF(J236="기능삭제",0,"")),"") -> 0.25 | Q236: =IFERROR(I236*P236,"") -> 1
B237: □ 산림경영 시뮬레이션(3D) | I237: =IF(F237="","",IF(F237="EI",4,IF(F237="EO",5.2,IF(F237="EQ",3.9,IF(F237="ILF",7.5,IF(F237="EIF",5.4)))))) | M237: =IFERROR(IF(J237="기능변경",K237/G237,""),"") | N237: =IFERROR(IF(J237="기능변경",L237/H237,""),"") | O237: =IF(J237="기능변경",IF(F237="ILF",N237,IF(F237="EIF","재검토",IF(M237=0,N237,IF(N237=0,M237,(M237+N237)/2)))),"") | P237: =IF(O237<>0,IF(J237="기능변경",IF(O237<=0.33,0.25,IF(O237>0.66,0.75,0.5)),IF(J237="기능삭제",0,"")),"") | Q237: =IFERROR(I237*P237,"")
B238: 산림경영관리 모의 | C238: 산림공간측정 | D238: 면 측정 | F238: EO | G238: 2 | H238: 2 | I238: =IF(F238="","",IF(F238="EI",4,IF(F238="EO",5.2,IF(F238="EQ",3.9,IF(F238="ILF",7.5,IF(F238="EIF",5.4)))))) -> 5.2 | J238: 기능변경 | K238: 1 | L238: 1 | M238: =IFERROR(IF(J238="기능변경",K238/G238,""),"") -> 0.5 | N238: =IFERROR(IF(J238="기능변경",L238/H238,""),"") -> 0.5 | O238: =IF(J238="기능변경",IF(F238="ILF",N238,IF(F238="EIF","재검토",IF(M238=0,N238,IF(N238=0,M238,(M238+N238)/2)))),"") -> 0.5 | P238: =IF(O238<>0,IF(J238="기능변경",IF(O238<=0.33,0.25,IF(O238>0.66,0.75,0.5)),IF(J238="기능삭제",0,"")),"") -> 0.5 | Q238: =IFERROR(I238*P238,"") -> 2.6
C239: 계측 및 중첩 | D239: 임상도 계측 및 중첩 | F239: EO | I239: =IF(F239="","",IF(F239="EI",4,IF(F239="EO",5.2,IF(F239="EQ",3.9,IF(F239="ILF",7.5,IF(F239="EIF",5.4)))))) -> 5.2 | J239: 신규개발 | M239: =IFERROR(IF(J239="기능변경",K239/G239,""),"") | N239: =IFERROR(IF(J239="기능변경",L239/H239,""),"") | O239: =IF(J239="기능변경",IF(F239="ILF",N239,IF(F239="EIF","재검토",IF(M239=0,N239,IF(N239=0,M239,(M239+N239)/2)))),"") | P239: =IF(O239<>0,IF(J239="기능변경",IF(O239<=0.33,0.25,IF(O239>0.66,0.75,0.5)),IF(J239="기능삭제",0,"")),"") | Q239: =IFERROR(I239*P239,"")
D240: 입지토양도 계측 및 중첩 | F240: EO | I240: =IF(F240="","",IF(F240="EI",4,IF(F240="EO",5.2,IF(F240="EQ",3.9,IF(F240="ILF",7.5,IF(F240="EIF",5.4)))))) -> 5.2 | J240: 신규개발 | M240: =IFERROR(IF(J240="기능변경",K240/G240,""),"") | N240: =IFERROR(IF(J240="기능변경",L240/H240,""),"") | O240: =IF(J240="기능변경",IF(F240="ILF",N240,IF(F240="EIF","재검토",IF(M240=0,N240,IF(N240=0,M240,(M240+N240)/2)))),"") | P240: =IF(O240<>0,IF(J240="기능변경",IF(O240<=0.33,0.25,IF(O240>0.66,0.75,0.5)),IF(J240="기능삭제",0,"")),"") | Q240: =IFERROR(I240*P240,"")
D241: 임도망도 계측 및 중첩 | F241: EO | I241: =IF(F241="","",IF(F241="EI",4,IF(F241="EO",5.2,IF(F241="EQ",3.9,IF(F241="ILF",7.5,IF(F241="EIF",5.4)))))) -> 5.2 | J241: 신규개발 | M241: =IFERROR(IF(J241="기능변경",K241/G241,""),"") | N241: =IFERROR(IF(J241="기능변경",L241/H241,""),"") | O241: =IF(J241="기능변경",IF(F241="ILF",N241,IF(F241="EIF","재검토",IF(M241=0,N241,IF(N241=0,M241,(M241+N241)/2)))),"") | P241: =IF(O241<>0,IF(J241="기능변경",IF(O241<=0.33,0.25,IF(O241>0.66,0.75,0.5)),IF(J241="기능삭제",0,"")),"") | Q241: =IFERROR(I241*P241,"")
D242: DEM 예측 및 중첩 | F242: EO | I242: =IF(F242="","",IF(F242="EI",4,IF(F242="EO",5.2,IF(F242="EQ",3.9,IF(F242="ILF",7.5,IF(F242="EIF",5.4)))))) -> 5.2 | J242: 신규개발 | M242: =IFERROR(IF(J242="기능변경",K242/G242,""),"") | N242: =IFERROR(IF(J242="기능변경",L242/H242,""),"") | O242: =IF(J242="기능변경",IF(F242="ILF",N242,IF(F242="EIF","재검토",IF(M242=0,N242,IF(N242=0,M242,(M242+N242)/2)))),"") | P242: =IF(O242<>0,IF(J242="기능변경",IF(O242<=0.33,0.25,IF(O242>0.66,0.75,0.5)),IF(J242="기능삭제",0,"")),"") | Q242: =IFERROR(I242*P242,"")
D243: 임소반도 계측 및 중첩 | F243: EO | I243: =IF(F243="","",IF(F243="EI",4,IF(F243="EO",5.2,IF(F243="EQ",3.9,IF(F243="ILF",7.5,IF(F243="EIF",5.4)))))) -> 5.2 | J243: 신규개발 | M243: =IFERROR(IF(J243="기능변경",K243/G243,""),"") | N243: =IFERROR(IF(J243="기능변경",L243/H243,""),"") | O243: =IF(J243="기능변경",IF(F243="ILF",N243,IF(F243="EIF","재검토",IF(M243=0,N243,IF(N243=0,M243,(M243+N243)/2)))),"") | P243: =IF(O243<>0,IF(J243="기능변경",IF(O243<=0.33,0.25,IF(O243>0.66,0.75,0.5)),IF(J243="기능삭제",0,"")),"") | Q243: =IFERROR(I243*P243,"")
D244: 경영이력정보 계측 및 중첩 | F244: EO | I244: =IF(F244="","",IF(F244="EI",4,IF(F244="EO",5.2,IF(F244="EQ",3.9,IF(F244="ILF",7.5,IF(F244="EIF",5.4)))))) -> 5.2 | J244: 신규개발 | M244: =IFERROR(IF(J244="기능변경",K244/G244,""),"") | N244: =IFERROR(IF(J244="기능변경",L244/H244,""),"") | O244: =IF(J244="기능변경",IF(F244="ILF",N244,IF(F244="EIF","재검토",IF(M244=0,N244,IF(N244=0,M244,(M244+N244)/2)))),"") | P244: =IF(O244<>0,IF(J244="기능변경",IF(O244<=0.33,0.25,IF(O244>0.66,0.75,0.5)),IF(J244="기능삭제",0,"")),"") | Q244: =IFERROR(I244*P244,"")
C245: 레이어관리 | D245: 레이어 업로드 | F245: EI | G245: 2 | H245: 2 | I245: =IF(F245="","",IF(F245="EI",4,IF(F245="EO",5.2,IF(F245="EQ",3.9,IF(F245="ILF",7.5,IF(F245="EIF",5.4)))))) -> 4 | J245: 기능변경 | K245: 1 | L245: 1 | M245: =IFERROR(IF(J245="기능변경",K245/G245,""),"") -> 0.5 | N245: =IFERROR(IF(J245="기능변경",L245/H245,""),"") -> 0.5 | O245: =IF(J245="기능변경",IF(F245="ILF",N245,IF(F245="EIF","재검토",IF(M245=0,N245,IF(N245=0,M245,(M245+N245)/2)))),"") -> 0.5 | P245: =IF(O245<>0,IF(J245="기능변경",IF(O245<=0.33,0.25,IF(O245>0.66,0.75,0.5)),IF(J245="기능삭제",0,"")),"") -> 0.5 | Q245: =IFERROR(I245*P245,"") -> 2
C246: 속성정보조회 | D246: 확대 | F246: EQ | G246: 2 | H246: 2 | I246: =IF(F246="","",IF(F246="EI",4,IF(F246="EO",5.2,IF(F246="EQ",3.9,IF(F246="ILF",7.5,IF(F246="EIF",5.4)))))) -> 3.9 | J246: 기능변경 | K246: 1 | L246: 1 | M246: =IFERROR(IF(J246="기능변경",K246/G246,""),"") -> 0.5 | N246: =IFERROR(IF(J246="기능변경",L246/H246,""),"") -> 0.5 | O246: =IF(J246="기능변경",IF(F246="ILF",N246,IF(F246="EIF","재검토",IF(M246=0,N246,IF(N246=0,M246,(M246+N246)/2)))),"") -> 0.5 | P246: =IF(O246<>0,IF(J246="기능변경",IF(O246<=0.33,0.25,IF(O246>0.66,0.75,0.5)),IF(J246="기능삭제",0,"")),"") -> 0.5 | Q246: =IFERROR(I246*P246,"") -> 1.95
D247: 축소 | F247: EQ | G247: 2 | H247: 2 | I247: =IF(F247="","",IF(F247="EI",4,IF(F247="EO",5.2,IF(F247="EQ",3.9,IF(F247="ILF",7.5,IF(F247="EIF",5.4)))))) -> 3.9 | J247: 기능변경 | K247: 1 | L247: 1 | M247: =IFERROR(IF(J247="기능변경",K247/G247,""),"") -> 0.5 | N247: =IFERROR(IF(J247="기능변경",L247/H247,""),"") -> 0.5 | O247: =IF(J247="기능변경",IF(F247="ILF",N247,IF(F247="EIF","재검토",IF(M247=0,N247,IF(N247=0,M247,(M247+N247)/2)))),"") -> 0.5 | P247: =IF(O247<>0,IF(J247="기능변경",IF(O247<=0.33,0.25,IF(O247>0.66,0.75,0.5)),IF(J247="기능삭제",0,"")),"") -> 0.5 | Q247: =IFERROR(I247*P247,"") -> 1.95
D248: 줌 | F248: EQ | G248: 2 | H248: 2 | I248: =IF(F248="","",IF(F248="EI",4,IF(F248="EO",5.2,IF(F248="EQ",3.9,IF(F248="ILF",7.5,IF(F248="EIF",5.4)))))) -> 3.9 | J248: 기능변경 | K248: 1 | L248: 1 | M248: =IFERROR(IF(J248="기능변경",K248/G248,""),"") -> 0.5 | N248: =IFERROR(IF(J248="기능변경",L248/H248,""),"") -> 0.5 | O248: =IF(J248="기능변경",IF(F248="ILF",N248,IF(F248="EIF","재검토",IF(M248=0,N248,IF(N248=0,M248,(M248+N248)/2)))),"") -> 0.5 | P248: =IF(O248<>0,IF(J248="기능변경",IF(O248<=0.33,0.25,IF(O248>0.66,0.75,0.5)),IF(J248="기능삭제",0,"")),"") -> 0.5 | Q248: =IFERROR(I248*P248,"") -> 1.95
D249: 이동 | F249: EQ | G249: 2 | H249: 2 | I249: =IF(F249="","",IF(F249="EI",4,IF(F249="EO",5.2,IF(F249="EQ",3.9,IF(F249="ILF",7.5,IF(F249="EIF",5.4)))))) -> 3.9 | J249: 기능변경 | K249: 1 | L249: 1 | M249: =IFERROR(IF(J249="기능변경",K249/G249,""),"") -> 0.5 | N249: =IFERROR(IF(J249="기능변경",L249/H249,""),"") -> 0.5 | O249: =IF(J249="기능변경",IF(F249="ILF",N249,IF(F249="EIF","재검토",IF(M249=0,N249,IF(N249=0,M249,(M249+N249)/2)))),"") -> 0.5 | P249: =IF(O249<>0,IF(J249="기능변경",IF(O249<=0.33,0.25,IF(O249>0.66,0.75,0.5)),IF(J249="기능삭제",0,"")),"") -> 0.5 | Q249: =IFERROR(I249*P249,"") -> 1.95
D250: 홈 귀환 | F250: EQ | G250: 2 | H250: 2 | I250: =IF(F250="","",IF(F250="EI",4,IF(F250="EO",5.2,IF(F250="EQ",3.9,IF(F250="ILF",7.5,IF(F250="EIF",5.4)))))) -> 3.9 | J250: 기능변경 | K250: 1 | L250: 1 | M250: =IFERROR(IF(J250="기능변경",K250/G250,""),"") -> 0.5 | N250: =IFERROR(IF(J250="기능변경",L250/H250,""),"") -> 0.5 | O250: =IF(J250="기능변경",IF(F250="ILF",N250,IF(F250="EIF","재검토",IF(M250=0,N250,IF(N250=0,M250,(M250+N250)/2)))),"") -> 0.5 | P250: =IF(O250<>0,IF(J250="기능변경",IF(O250<=0.33,0.25,IF(O250>0.66,0.75,0.5)),IF(J250="기능삭제",0,"")),"") -> 0.5 | Q250: =IFERROR(I250*P250,"") -> 1.95
D251: 회전 | F251: EQ | G251: 2 | H251: 2 | I251: =IF(F251="","",IF(F251="EI",4,IF(F251="EO",5.2,IF(F251="EQ",3.9,IF(F251="ILF",7.5,IF(F251="EIF",5.4)))))) -> 3.9 | J251: 기능변경 | K251: 1 | L251: 1 | M251: =IFERROR(IF(J251="기능변경",K251/G251,""),"") -> 0.5 | N251: =IFERROR(IF(J251="기능변경",L251/H251,""),"") -> 0.5 | O251: =IF(J251="기능변경",IF(F251="ILF",N251,IF(F251="EIF","재검토",IF(M251=0,N251,IF(N251=0,M251,(M251+N251)/2)))),"") -> 0.5 | P251: =IF(O251<>0,IF(J251="기능변경",IF(O251<=0.33,0.25,IF(O251>0.66,0.75,0.5)),IF(J251="기능삭제",0,"")),"") -> 0.5 | Q251: =IFERROR(I251*P251,"") -> 1.95
D252: 나침반 보기 | F252: EO | G252: 2 | H252: 2 | I252: =IF(F252="","",IF(F252="EI",4,IF(F252="EO",5.2,IF(F252="EQ",3.9,IF(F252="ILF",7.5,IF(F252="EIF",5.4)))))) -> 5.2 | J252: 기능변경 | K252: 1 | L252: 1 | M252: =IFERROR(IF(J252="기능변경",K252/G252,""),"") -> 0.5 | N252: =IFERROR(IF(J252="기능변경",L252/H252,""),"") -> 0.5 | O252: =IF(J252="기능변경",IF(F252="ILF",N252,IF(F252="EIF","재검토",IF(M252=0,N252,IF(N252=0,M252,(M252+N252)/2)))),"") -> 0.5 | P252: =IF(O252<>0,IF(J252="기능변경",IF(O252<=0.33,0.25,IF(O252>0.66,0.75,0.5)),IF(J252="기능삭제",0,"")),"") -> 0.5 | Q252: =IFERROR(I252*P252,"") -> 2.6
D253: 범례보기 | F253: EQ | G253: 2 | H253: 2 | I253: =IF(F253="","",IF(F253="EI",4,IF(F253="EO",5.2,IF(F253="EQ",3.9,IF(F253="ILF",7.5,IF(F253="EIF",5.4)))))) -> 3.9 | J253: 기능변경 | K253: 1 | L253: 1 | M253: =IFERROR(IF(J253="기능변경",K253/G253,""),"") -> 0.5 | N253: =IFERROR(IF(J253="기능변경",L253/H253,""),"") -> 0.5 | O253: =IF(J253="기능변경",IF(F253="ILF",N253,IF(F253="EIF","재검토",IF(M253=0,N253,IF(N253=0,M253,(M253+N253)/2)))),"") -> 0.5 | P253: =IF(O253<>0,IF(J253="기능변경",IF(O253<=0.33,0.25,IF(O253>0.66,0.75,0.5)),IF(J253="기능삭제",0,"")),"") -> 0.5 | Q253: =IFERROR(I253*P253,"") -> 1.95
D254: 통합검색 | F254: EQ | G254: 2 | H254: 2 | I254: =IF(F254="","",IF(F254="EI",4,IF(F254="EO",5.2,IF(F254="EQ",3.9,IF(F254="ILF",7.5,IF(F254="EIF",5.4)))))) -> 3.9 | J254: 기능변경 | K254: 1 | L254: 1 | M254: =IFERROR(IF(J254="기능변경",K254/G254,""),"") -> 0.5 | N254: =IFERROR(IF(J254="기능변경",L254/H254,""),"") -> 0.5 | O254: =IF(J254="기능변경",IF(F254="ILF",N254,IF(F254="EIF","재검토",IF(M254=0,N254,IF(N254=0,M254,(M254+N254)/2)))),"") -> 0.5 | P254: =IF(O254<>0,IF(J254="기능변경",IF(O254<=0.33,0.25,IF(O254>0.66,0.75,0.5)),IF(J254="기능삭제",0,"")),"") -> 0.5 | Q254: =IFERROR(I254*P254,"") -> 1.95
D255: 도로명 주소 검색 | F255: EQ | G255: 2 | H255: 2 | I255: =IF(F255="","",IF(F255="EI",4,IF(F255="EO",5.2,IF(F255="EQ",3.9,IF(F255="ILF",7.5,IF(F255="EIF",5.4)))))) -> 3.9 | J255: 기능변경 | K255: 1 | L255: 1 | M255: =IFERROR(IF(J255="기능변경",K255/G255,""),"") -> 0.5 | N255: =IFERROR(IF(J255="기능변경",L255/H255,""),"") -> 0.5 | O255: =IF(J255="기능변경",IF(F255="ILF",N255,IF(F255="EIF","재검토",IF(M255=0,N255,IF(N255=0,M255,(M255+N255)/2)))),"") -> 0.5 | P255: =IF(O255<>0,IF(J255="기능변경",IF(O255<=0.33,0.25,IF(O255>0.66,0.75,0.5)),IF(J255="기능삭제",0,"")),"") -> 0.5 | Q255: =IFERROR(I255*P255,"") -> 1.95
...

Sheet 5.대국민서비스
B1: "산림공간 디지털플랫폼 사업_대국민서비스" 소프트웨어 재개발비 산정
N2: (소프트웨어사업 대가산정 가이드, 2024. KOSA)
B4: ○ 재개발비 산정 | N4: (단위 : 원)
B5: 신규개발 | E5: 신규개발 기능 규모 | G5: ='5-1.FP산정(재개발, 간이법)'!K2 -> 7.9
B6: 수정없이 재사용 | E6: 수정없이 재사용 대상 기능 규모 | G6: ='5-1.FP산정(재개발, 간이법)'!K5 -> 10.8 | J6: 시험단계 비율 (0~25%) | M6: 0.25
E7: 수정없이 재사용 기능 규모 | G7: =G6*M6 -> 2.7
B8: 수정 후 재사용 | E8: 기능변경 규모 | G8: ='5-1.FP산정(재개발, 간이법)'!K3 -> 103.35
E9: 재사용 난이도 | G9: =1+((L9+L10)/2)/100*0.8 -> 1.28 | I9: 구조화 및 애플리케이션 명확화 정도 | L9: =HLOOKUP(N9,P9:T10,2,FALSE) -> 40 | N9: 어려움 | P9: 매우 어려움 | Q9: 어려움 | R9: 보통 | S9: 쉬움 | T9: 매우 쉬움
I10: 문서화 및 소스코드 서술화 정도 | L10: =HLOOKUP(N10,P9:T10,2,0) -> 30 | N10: 보통 | P10: 50 | Q10: 40 | R10: 30 | S10: 20 | T10: 10
E11: 수정 후 재사용 기능 규모 | G11: =G8*G9 -> 132.288
B12: 재개발 기능 규모 | E12: =G5+G7+G11 -> 142.888 | K12: 기능점수당 단가 | M12: 605784
B13: 보정전 재개발원가 | E13: =E12*M12 -> 86559264
B14: 보정계수 | E14: 규모 | G14: 연계복잡성 | I14: 성능 | K14: 운영환경 호환성 | M14: 보안성
E15: =M32 -> 1.28 | G15: =M33 -> 1 | I15: =M34 -> 1.05 | K15: =M35 -> 1.13 | M15: =M36 -> 1.03
B16: 보정후 재개발원가 | E16: =E13*E15*G15*I15*K15*M15 -> 1.3540306e+08
B17: 직접경비 | E17: =M28 -> 0
B18: 이윤 | D18: 0.2 | E18: =E16*D18 -> 27080613
B19: 재개발 사업대가 (부가세 별도) | E19: =SUM(E16:N18) -> 1.6248368e+08
B20: 재개발 사업대가 (부가세 포함) | E20: =E19*1.1 -> 1.7873204e+08
B23: ○ 직접경비 | N23: (단위 : 원)
B24: 항목 | E24: 산출내역 | M24: 금액
B28: 합 계 | M28: =SUM(M25:N27) -> 0
B30: ※ 보정계수 산정
B31: 보정계수 구분 | E31: 복잡도 및 난이도 수준 | M31: 보정계수
B32: SW규모 | E32: ="= 0.4057 x (log e("&E12&") - 7.1978)^2 + 0.8878 (단, 500FP 미만 1.28, 3,000FP 초과 1.153 적용)" -> = 0.4057 x (log e(142.888) - 7.1978)^2 + 0.8878 (단, 500FP 미만 1.28, 3,000FP 초과 1.153 적용) | M32: =IF(E12<500,1.28,IF(E12>3000,1.153,0.4057*(LN(E12)-7.1978)^2+0.8878)) -> 1.28
B33: 연계복잡성 | E33: 3. 3~5개의 타 기관 연계 | M33: =VLOOKUP(E33,P33:Q37,2,1) -> 1 | P33: 1. 타 기관 연계 없음 | Q33: 0.88
B34: 성능 요구수준 | E34: 4. 응답시간이나 처리율이 모든 업무시간에 중요하며, 처리 시한이 명시되어 있다. | M34: =VLOOKUP(E34,P38:Q42,2,1) -> 1.05 | P34: 2. 1~2개의 타 기관 연계 | Q34: 0.94
B35: 운영환경 호환성 | E35: 4. 운영환경 호환성에 대한 요구사항이 있으며, 이질적인 하드웨어 및 소프트웨어 환경에서 운영되도록 설계된다. | M35: =VLOOKUP(E35,P43:Q47,2,1) -> 1.13 | P35: 3. 3~5개의 타 기관 연계 | Q35: 1
B36: 보안성 요구수준 | E36: 3. 3가지 요구사항이 포함되어 있다. | M36: =VLOOKUP(E36,P48:Q52,2,1) -> 1.03 | P36: 4. 6~10개의 타 기관 연계 | Q36: 1.06
P37: 5. 10개 초과의 타 기관 연계 | Q37: 1.12
P38: 1. 응답성능에 대한 특별한 요구사항이 없다. | Q38: 0.91
P39: 2. 응답성능에 대한 요구사항이 있으나 특별한 조치가 필요하지는 않다. | Q39: 0.95
P40: 3. 응답시간이나 처리율이 피크타임(peak time)에 중요하며, 처리 시한이 명시되어 있다. | Q40: 1
P41: 4. 응답시간이나 처리율이 모든 업무시간에 중요하며, 처리 시한이 명시되어 있다. | Q41: 1.05
